Workbook

Sheet 整月外場班表
A1: 7月 | D1: 應排休天數: | H1: 9 | I1: 天( | J1: 5 | K1: 例 | L1: 4 | M1: 休 | O1: 國) | Q1: 指休 | T1: 排休 | X1: 補休 | AA1: 病假 | AD1: 上課/開會 | AH1: 特休 | AK1: 門店A | AN1: 門店B | AQ1: 門店C
A2: 行政工作 清潔保養 | BN2: 上班 天數
A3: 行銷活動 | F3: 點數 加倍 | N3: 微醺 | T3: 點數 加倍 | BN3: 31
A4: 白霧時光 板橋傑仕堡 | C4: 月底 連上 | D4: 46204 | F4: 46205 | H4: 46206 | J4: 46207 | L4: 46208 | N4: 46209 | P4: 46210 | R4: 46211 | T4: 46212 | V4: 46213 | X4: 46214 | Z4: 46215 | AB4: 46216 | AD4: 46217 | AF4: 46218 | AH4: 46219 | AJ4: 46220 | AL4: 46221 | AN4: 46222 | AP4: 46223 | AR4: 46224 | AT4: 46225 | AV4: 46226 | AX4: 46227 | AZ4: 46228 | BB4: 46229 | BD4: 46230 | BF4: 46231 | BH4: 46232 | BJ4: 46233 | BL4: 46234 | BN4: 應上時數
D5: =D4 -> 46204 | F5: =F4 -> 46205 | H5: =H4 -> 46206 | J5: =J4 -> 46207 | L5: =L4 -> 46208 | N5: =N4 -> 46209 | P5: =P4 -> 46210 | R5: =R4 -> 46211 | T5: =T4 -> 46212 | V5: =V4 -> 46213 | X5: =X4 -> 46214 | Z5: =Z4 -> 46215 | AB5: =AB4 -> 46216 | AD5: =AD4 -> 46217 | AF5: =AF4 -> 46218 | AH5: =AH4 -> 46219 | AJ5: =AJ4 -> 46220 | AL5: =AL4 -> 46221 | AN5: =AN4 -> 46222 | AP5: =AP4 -> 46223 | AR5: =AR4 -> 46224 | AT5: =AT4 -> 46225 | AV5: =AV4 -> 46226 | AX5: =AX4 -> 46227 | AZ5: =AZ4 -> 46228 | BB5: =BB4 -> 46229 | BD5: =BD4 -> 46230 | BF5: =BF4 -> 46231 | BH5: =BH4 -> 46232 | BJ5: =BJ4 -> 46233 | BL5: =BL4 -> 46234 | BN5: 112
A6: 儲備幹部 | B6: 張意昕
BN7: =BN8-$BN$5 -> -112
A8: 22040023 | D8: =(E6-D6)+(E7-D7) -> 0 | F8: =(G6-F6)+(G7-F7) -> 0 | H8: =(I6-H6)+(I7-H7) -> 0 | J8: =(K6-J6)+(K7-J7) -> 0 | L8: =(M6-L6)+(M7-L7) -> 0 | N8: =(O6-N6)+(O7-N7) -> 0 | P8: =(Q6-P6)+(Q7-P7) -> 0 | R8: =(S6-R6)+(S7-R7) -> 0 | T8: =(U6-T6)+(U7-T7) -> 0 | V8: =(W6-V6)+(W7-V7) -> 0 | X8: =(Y6-X6)+(Y7-X7) -> 0 | Z8: =(AA6-Z6)+(AA7-Z7) -> 0 | AB8: =(AC6-AB6)+(AC7-AB7) -> 0 | AD8: =(AE6-AD6)+(AE7-AD7) -> 0 | AF8: =(AG6-AF6)+(AG7-AF7) -> 0 | AH8: =(AI6-AH6)+(AI7-AH7) -> 0 | AJ8: =(AK6-AJ6)+(AK7-AJ7) -> 0 | AL8: =(AM6-AL6)+(AM7-AL7) -> 0 | AN8: =(AO6-AN6)+(AO7-AN7) -> 0 | AP8: =(AQ6-AP6)+(AQ7-AP7) -> 0 | AR8: =(AS6-AR6)+(AS7-AR7) -> 0 | AT8: =(AU6-AT6)+(AU7-AT7) -> 0 | AV8: =(AW6-AV6)+(AW7-AV7) -> 0 | AX8: =(AY6-AX6)+(AY7-AX7) -> 0 | AZ8: =(BA6-AZ6)+(BA7-AZ7) -> 0 | BB8: =(BC6-BB6)+(BC7-BB7) -> 0 | BD8: =(BE6-BD6)+(BE7-BD7) -> 0 | BF8: =(BG6-BF6)+(BG7-BF7) -> 0 | BH8: =(BI6-BH6)+(BI7-BH7) -> 0 | BJ8: =(BK6-BJ6)+(BK7-BJ7) -> 0 | BL8: =(BM6-BL6)+(BM7-BL7) -> 0 | BN8: =SUM(D8:BM8) -> 0
A9: 儲備幹部 | B9: 楊衡欣
BN10: =BN11-$BN$5 -> -112
D11: =(E9-D9)+(E10-D10) -> 0 | F11: =(G9-F9)+(G10-F10) -> 0 | H11: =(I9-H9)+(I10-H10) -> 0 | J11: =(K9-J9)+(K10-J10) -> 0 | L11: =(M9-L9)+(M10-L10) -> 0 | N11: =(O9-N9)+(O10-N10) -> 0 | P11: =(Q9-P9)+(Q10-P10) -> 0 | R11: =(S9-R9)+(S10-R10) -> 0 | T11: =(U9-T9)+(U10-T10) -> 0 | V11: =(W9-V9)+(W10-V10) -> 0 | X11: =(Y9-X9)+(Y10-X10) -> 0 | Z11: =(AA9-Z9)+(AA10-Z10) -> 0 | AB11: =(AC9-AB9)+(AC10-AB10) -> 0 | AD11: =(AE9-AD9)+(AE10-AD10) -> 0 | AF11: =(AG9-AF9)+(AG10-AF10) -> 0 | AH11: =(AI9-AH9)+(AI10-AH10) -> 0 | AJ11: =(AK9-AJ9)+(AK10-AJ10) -> 0 | AL11: =(AM9-AL9)+(AM10-AL10) -> 0 | AN11: =(AO9-AN9)+(AO10-AN10) -> 0 | AP11: =(AQ9-AP9)+(AQ10-AP10) -> 0 | AR11: =(AS9-AR9)+(AS10-AR10) -> 0 | AT11: =(AU9-AT9)+(AU10-AT10) -> 0 | AV11: =(AW9-AV9)+(AW10-AV10) -> 0 | AX11: =(AY9-AX9)+(AY10-AX10) -> 0 | AZ11: =(BA9-AZ9)+(BA10-AZ10) -> 0 | BB11: =(BC9-BB9)+(BC10-BB10) -> 0 | BD11: =(BE9-BD9)+(BE10-BD10) -> 0 | BF11: =(BG9-BF9)+(BG10-BF10) -> 0 | BH11: =(BI9-BH9)+(BI10-BH10) -> 0 | BJ11: =(BK9-BJ9)+(BK10-BJ10) -> 0 | BL11: =(BM9-BL9)+(BM10-BL10) -> 0 | BN11: =SUM(D11:BM11) -> 0
A12: 儲備幹部 | B12: 宋文馨
BN13: =BN14-$BN$5 -> -112
D14: =(E12-D12)+(E13-D13) -> 0 | F14: =(G12-F12)+(G13-F13) -> 0 | H14: =(I12-H12)+(I13-H13) -> 0 | J14: =(K12-J12)+(K13-J13) -> 0 | L14: =(M12-L12)+(M13-L13) -> 0 | N14: =(O12-N12)+(O13-N13) -> 0 | P14: =(Q12-P12)+(Q13-P13) -> 0 | R14: =(S12-R12)+(S13-R13) -> 0 | T14: =(U12-T12)+(U13-T13) -> 0 | V14: =(W12-V12)+(W13-V13) -> 0 | X14: =(Y12-X12)+(Y13-X13) -> 0 | Z14: =(AA12-Z12)+(AA13-Z13) -> 0 | AB14: =(AC12-AB12)+(AC13-AB13) -> 0 | AD14: =(AE12-AD12)+(AE13-AD13) -> 0 | AF14: =(AG12-AF12)+(AG13-AF13) -> 0 | AH14: =(AI12-AH12)+(AI13-AH13) -> 0 | AJ14: =(AK12-AJ12)+(AK13-AJ13) -> 0 | AL14: =(AM12-AL12)+(AM13-AL13) -> 0 | AN14: =(AO12-AN12)+(AO13-AN13) -> 0 | AP14: =(AQ12-AP12)+(AQ13-AP13) -> 0 | AR14: =(AS12-AR12)+(AS13-AR13) -> 0 | AT14: =(AU12-AT12)+(AU13-AT13) -> 0 | AV14: =(AW12-AV12)+(AW13-AV13) -> 0 | AX14: =(AY12-AX12)+(AY13-AX13) -> 0 | AZ14: =(BA12-AZ12)+(BA13-AZ13) -> 0 | BB14: =(BC12-BB12)+(BC13-BB13) -> 0 | BD14: =(BE12-BD12)+(BE13-BD13) -> 0 | BF14: =(BG12-BF12)+(BG13-BF13) -> 0 | BH14: =(BI12-BH12)+(BI13-BH13) -> 0 | BJ14: =(BK12-BJ12)+(BK13-BJ13) -> 0 | BL14: =(BM12-BL12)+(BM13-BL13) -> 0 | BN14: =SUM(D14:BM14) -> 0
A15: 正職 | B15: 程楚茜
BN16: =BN17-$BN$5 -> -112
D17: =(E15-D15)+(E16-D16) -> 0 | F17: =(G15-F15)+(G16-F16) -> 0 | H17: =(I15-H15)+(I16-H16) -> 0 | J17: =(K15-J15)+(K16-J16) -> 0 | L17: =(M15-L15)+(M16-L16) -> 0 | N17: =(O15-N15)+(O16-N16) -> 0 | P17: =(Q15-P15)+(Q16-P16) -> 0 | R17: =(S15-R15)+(S16-R16) -> 0 | T17: =(U15-T15)+(U16-T16) -> 0 | V17: =(W15-V15)+(W16-V16) -> 0 | X17: =(Y15-X15)+(Y16-X16) -> 0 | Z17: =(AA15-Z15)+(AA16-Z16) -> 0 | AB17: =(AC15-AB15)+(AC16-AB16) -> 0 | AD17: =(AE15-AD15)+(AE16-AD16) -> 0 | AF17: =(AG15-AF15)+(AG16-AF16) -> 0 | AH17: =(AI15-AH15)+(AI16-AH16) -> 0 | AJ17: =(AK15-AJ15)+(AK16-AJ16) -> 0 | AL17: =(AM15-AL15)+(AM16-AL16) -> 0 | AN17: =(AO15-AN15)+(AO16-AN16) -> 0 | AP17: =(AQ15-AP15)+(AQ16-AP16) -> 0 | AR17: =(AS15-AR15)+(AS16-AR16) -> 0 | AT17: =(AU15-AT15)+(AU16-AT16) -> 0 | AV17: =(AW15-AV15)+(AW16-AV16) -> 0 | AX17: =(AY15-AX15)+(AY16-AX16) -> 0 | AZ17: =(BA15-AZ15)+(BA16-AZ16) -> 0 | BB17: =(BC15-BB15)+(BC16-BB16) -> 0 | BD17: =(BE15-BD15)+(BE16-BD16) -> 0 | BF17: =(BG15-BF15)+(BG16-BF16) -> 0 | BH17: =(BI15-BH15)+(BI16-BH16) -> 0 | BJ17: =(BK15-BJ15)+(BK16-BJ16) -> 0 | BL17: =(BM15-BL15)+(BM16-BL16) -> 0 | BN17: =SUM(D17:BM17) -> 0
A18: 正職 | B18: 林郁珮
BN19: =BN20-$BN$5 -> -112
D20: =(E18-D18)+(E19-D19) -> 0 | F20: =(G18-F18)+(G19-F19) -> 0 | H20: =(I18-H18)+(I19-H19) -> 0 | J20: =(K18-J18)+(K19-J19) -> 0 | L20: =(M18-L18)+(M19-L19) -> 0 | N20: =(O18-N18)+(O19-N19) -> 0 | P20: =(Q18-P18)+(Q19-P19) -> 0 | R20: =(S18-R18)+(S19-R19) -> 0 | T20: =(U18-T18)+(U19-T19) -> 0 | V20: =(W18-V18)+(W19-V19) -> 0 | X20: =(Y18-X18)+(Y19-X19) -> 0 | Z20: =(AA18-Z18)+(AA19-Z19) -> 0 | AB20: =(AC18-AB18)+(AC19-AB19) -> 0 | AD20: =(AE18-AD18)+(AE19-AD19) -> 0 | AF20: =(AG18-AF18)+(AG19-AF19) -> 0 | AH20: =(AI18-AH18)+(AI19-AH19) -> 0 | AJ20: =(AK18-AJ18)+(AK19-AJ19) -> 0 | AL20: =(AM18-AL18)+(AM19-AL19) -> 0 | AN20: =(AO18-AN18)+(AO19-AN19) -> 0 | AP20: =(AQ18-AP18)+(AQ19-AP19) -> 0 | AR20: =(AS18-AR18)+(AS19-AR19) -> 0 | AT20: =(AU18-AT18)+(AU19-AT19) -> 0 | AV20: =(AW18-AV18)+(AW19-AV19) -> 0 | AX20: =(AY18-AX18)+(AY19-AX19) -> 0 | AZ20: =(BA18-AZ18)+(BA19-AZ19) -> 0 | BB20: =(BC18-BB18)+(BC19-BB19) -> 0 | BD20: =(BE18-BD18)+(BE19-BD19) -> 0 | BF20: =(BG18-BF18)+(BG19-BF19) -> 0 | BH20: =(BI18-BH18)+(BI19-BH19) -> 0 | BJ20: =(BK18-BJ18)+(BK19-BJ19) -> 0 | BL20: =(BM18-BL18)+(BM19-BL19) -> 0 | BN20: =SUM(D20:BM20) -> 0
BN22: =BN23-$BN$5 -> -112
D23: =(E21-D21)+(E22-D22) -> 0 | F23: =(G21-F21)+(G22-F22) -> 0 | H23: =(I21-H21)+(I22-H22) -> 0 | J23: =(K21-J21)+(K22-J22) -> 0 | L23: =(M21-L21)+(M22-L22) -> 0 | N23: =(O21-N21)+(O22-N22) -> 0 | P23: =(Q21-P21)+(Q22-P22) -> 0 | R23: =(S21-R21)+(S22-R22) -> 0 | T23: =(U21-T21)+(U22-T22) -> 0 | V23: =(W21-V21)+(W22-V22) -> 0 | X23: =(Y21-X21)+(Y22-X22) -> 0 | Z23: =(AA21-Z21)+(AA22-Z22) -> 0 | AB23: =(AC21-AB21)+(AC22-AB22) -> 0 | AD23: =(AE21-AD21)+(AE22-AD22) -> 0 | AF23: =(AG21-AF21)+(AG22-AF22) -> 0 | AH23: =(AI21-AH21)+(AI22-AH22) -> 0 | AJ23: =(AK21-AJ21)+(AK22-AJ22) -> 0 | AL23: =(AM21-AL21)+(AM22-AL22) -> 0 | AN23: =(AO21-AN21)+(AO22-AN22) -> 0 | AP23: =(AQ21-AP21)+(AQ22-AP22) -> 0 | AR23: =(AS21-AR21)+(AS22-AR22) -> 0 | AT23: =(AU21-AT21)+(AU22-AT22) -> 0 | AV23: =(AW21-AV21)+(AW22-AV22) -> 0 | AX23: =(AY21-AX21)+(AY22-AX22) -> 0 | AZ23: =(BA21-AZ21)+(BA22-AZ22) -> 0 | BB23: =(BC21-BB21)+(BC22-BB22) -> 0 | BD23: =(BE21-BD21)+(BE22-BD22) -> 0 | BF23: =(BG21-BF21)+(BG22-BF22) -> 0 | BH23: =(BI21-BH21)+(BI22-BH22) -> 0 | BJ23: =(BK21-BJ21)+(BK22-BJ22) -> 0 | BL23: =(BM21-BL21)+(BM22-BL22) -> 0 | BN23: =SUM(D23:BM23) -> 0
BN25: =BN26-$BN$5 -> -112
D26: =(E24-D24)+(E25-D25) -> 0 | F26: =(G24-F24)+(G25-F25) -> 0 | H26: =(I24-H24)+(I25-H25) -> 0 | J26: =(K24-J24)+(K25-J25) -> 0 | L26: =(M24-L24)+(M25-L25) -> 0 | N26: =(O24-N24)+(O25-N25) -> 0 | P26: =(Q24-P24)+(Q25-P25) -> 0 | R26: =(S24-R24)+(S25-R25) -> 0 | T26: =(U24-T24)+(U25-T25) -> 0 | V26: =(W24-V24)+(W25-V25) -> 0 | X26: =(Y24-X24)+(Y25-X25) -> 0 | Z26: =(AA24-Z24)+(AA25-Z25) -> 0 | AB26: =(AC24-AB24)+(AC25-AB25) -> 0 | AD26: =(AE24-AD24)+(AE25-AD25) -> 0 | AF26: =(AG24-AF24)+(AG25-AF25) -> 0 | AH26: =(AI24-AH24)+(AI25-AH25) -> 0 | AJ26: =(AK24-AJ24)+(AK25-AJ25) -> 0 | AL26: =(AM24-AL24)+(AM25-AL25) -> 0 | AN26: =(AO24-AN24)+(AO25-AN25) -> 0 | AP26: =(AQ24-AP24)+(AQ25-AP25) -> 0 | AR26: =(AS24-AR24)+(AS25-AR25) -> 0 | AT26: =(AU24-AT24)+(AU25-AT25) -> 0 | AV26: =(AW24-AV24)+(AW25-AV25) -> 0 | AX26: =(AY24-AX24)+(AY25-AX25) -> 0 | AZ26: =(BA24-AZ24)+(BA25-AZ25) -> 0 | BB26: =(BC24-BB24)+(BC25-BB25) -> 0 | BD26: =(BE24-BD24)+(BE25-BD25) -> 0 | BF26: =(BG24-BF24)+(BG25-BF25) -> 0 | BH26: =(BI24-BH24)+(BI25-BH25) -> 0 | BJ26: =(BK24-BJ24)+(BK25-BJ25) -> 0 | BL26: =(BM24-BL24)+(BM25-BL25) -> 0 | BN26: =SUM(D26:BM26) -> 0
A27: 兼職 | B27: 黃先祺
BN28: =BN29-$BN$5 -> -112
A29: 25120137 | D29: =(E27-D27)+(E28-D28) -> 0 | F29: =(G27-F27)+(G28-F28) -> 0 | H29: =(I27-H27)+(I28-H28) -> 0 | J29: =(K27-J27)+(K28-J28) -> 0 | L29: =(M27-L27)+(M28-L28) -> 0 | N29: =(O27-N27)+(O28-N28) -> 0 | P29: =(Q27-P27)+(Q28-P28) -> 0 | R29: =(S27-R27)+(S28-R28) -> 0 | T29: =(U27-T27)+(U28-T28) -> 0 | V29: =(W27-V27)+(W28-V28) -> 0 | X29: =(Y27-X27)+(Y28-X28) -> 0 | Z29: =(AA27-Z27)+(AA28-Z28) -> 0 | AB29: =(AC27-AB27)+(AC28-AB28) -> 0 | AD29: =(AE27-AD27)+(AE28-AD28) -> 0 | AF29: =(AG27-AF27)+(AG28-AF28) -> 0 | AH29: =(AI27-AH27)+(AI28-AH28) -> 0 | AJ29: =(AK27-AJ27)+(AK28-AJ28) -> 0 | AL29: =(AM27-AL27)+(AM28-AL28) -> 0 | AN29: =(AO27-AN27)+(AO28-AN28) -> 0 | AP29: =(AQ27-AP27)+(AQ28-AP28) -> 0 | AR29: =(AS27-AR27)+(AS28-AR28) -> 0 | AT29: =(AU27-AT27)+(AU28-AT28) -> 0 | AV29: =(AW27-AV27)+(AW28-AV28) -> 0 | AX29: =(AY27-AX27)+(AY28-AX28) -> 0 | AZ29: =(BA27-AZ27)+(BA28-AZ28) -> 0 | BB29: =(BC27-BB27)+(BC28-BB28) -> 0 | BD29: =(BE27-BD27)+(BE28-BD28) -> 0 | BF29: =(BG27-BF27)+(BG28-BF28) -> 0 | BH29: =(BI27-BH27)+(BI28-BH28) -> 0 | BJ29: =(BK27-BJ27)+(BK28-BJ28) -> 0 | BL29: =(BM27-BL27)+(BM28-BL28) -> 0 | BN29: =SUM(D29:BM29) -> 0
BN31: =BN32-$BN$5 -> -112
D32: =(E30-D30)+(E31-D31) -> 0 | F32: =(G30-F30)+(G31-F31) -> 0 | H32: =(I30-H30)+(I31-H31) -> 0 | J32: =(K30-J30)+(K31-J31) -> 0 | L32: =(M30-L30)+(M31-L31) -> 0 | N32: =(O30-N30)+(O31-N31) -> 0 | P32: =(Q30-P30)+(Q31-P31) -> 0 | R32: =(S30-R30)+(S31-R31) -> 0 | T32: =(U30-T30)+(U31-T31) -> 0 | V32: =(W30-V30)+(W31-V31) -> 0 | X32: =(Y30-X30)+(Y31-X31) -> 0 | Z32: =(AA30-Z30)+(AA31-Z31) -> 0 | AB32: =(AC30-AB30)+(AC31-AB31) -> 0 | AD32: =(AE30-AD30)+(AE31-AD31) -> 0 | AF32: =(AG30-AF30)+(AG31-AF31) -> 0 | AH32: =(AI30-AH30)+(AI31-AH31) -> 0 | AJ32: =(AK30-AJ30)+(AK31-AJ31) -> 0 | AL32: =(AM30-AL30)+(AM31-AL31) -> 0 | AN32: =(AO30-AN30)+(AO31-AN31) -> 0 | AP32: =(AQ30-AP30)+(AQ31-AP31) -> 0 | AR32: =(AS30-AR30)+(AS31-AR31) -> 0 | AT32: =(AU30-AT30)+(AU31-AT31) -> 0 | AV32: =(AW30-AV30)+(AW31-AV31) -> 0 | AX32: =(AY30-AX30)+(AY31-AX31) -> 0 | AZ32: =(BA30-AZ30)+(BA31-AZ31) -> 0 | BB32: =(BC30-BB30)+(BC31-BB31) -> 0 | BD32: =(BE30-BD30)+(BE31-BD31) -> 0 | BF32: =(BG30-BF30)+(BG31-BF31) -> 0 | BH32: =(BI30-BH30)+(BI31-BH31) -> 0 | BJ32: =(BK30-BJ30)+(BK31-BJ31) -> 0 | BL32: =(BM30-BL30)+(BM31-BL31) -> 0 | BN32: =SUM(D32:BM32) -> 0
BN34: =BN35-$BN$5 -> -112
D35: =(E33-D33)+(E34-D34) -> 0 | F35: =(G33-F33)+(G34-F34) -> 0 | H35: =(I33-H33)+(I34-H34) -> 0 | J35: =(K33-J33)+(K34-J34) -> 0 | L35: =(M33-L33)+(M34-L34) -> 0 | N35: =(O33-N33)+(O34-N34) -> 0 | P35: =(Q33-P33)+(Q34-P34) -> 0 | R35: =(S33-R33)+(S34-R34) -> 0 | T35: =(U33-T33)+(U34-T34) -> 0 | V35: =(W33-V33)+(W34-V34) -> 0 | X35: =(Y33-X33)+(Y34-X34) -> 0 | Z35: =(AA33-Z33)+(AA34-Z34) -> 0 | AB35: =(AC33-AB33)+(AC34-AB34) -> 0 | AD35: =(AE33-AD33)+(AE34-AD34) -> 0 | AF35: =(AG33-AF33)+(AG34-AF34) -> 0 | AH35: =(AI33-AH33)+(AI34-AH34) -> 0 | AJ35: =(AK33-AJ33)+(AK34-AJ34) -> 0 | AL35: =(AM33-AL33)+(AM34-AL34) -> 0 | AN35: =(AO33-AN33)+(AO34-AN34) -> 0 | AP35: =(AQ33-AP33)+(AQ34-AP34) -> 0 | AR35: =(AS33-AR33)+(AS34-AR34) -> 0 | AT35: =(AU33-AT33)+(AU34-AT34) -> 0 | AV35: =(AW33-AV33)+(AW34-AV34) -> 0 | AX35: =(AY33-AX33)+(AY34-AX34) -> 0 | AZ35: =(BA33-AZ33)+(BA34-AZ34) -> 0 | BB35: =(BC33-BB33)+(BC34-BB34) -> 0 | BD35: =(BE33-BD33)+(BE34-BD34) -> 0 | BF35: =(BG33-BF33)+(BG34-BF34) -> 0 | BH35: =(BI33-BH33)+(BI34-BH34) -> 0 | BJ35: =(BK33-BJ33)+(BK34-BJ34) -> 0 | BL35: =(BM33-BL33)+(BM34-BL34) -> 0 | BN35: =SUM(D35:BM35) -> 0
BN37: =BN38-$BN$5 -> -112
D38: =(E36-D36)+(E37-D37) -> 0 | F38: =(G36-F36)+(G37-F37) -> 0 | H38: =(I36-H36)+(I37-H37) -> 0 | J38: =(K36-J36)+(K37-J37) -> 0 | L38: =(M36-L36)+(M37-L37) -> 0 | N38: =(O36-N36)+(O37-N37) -> 0 | P38: =(Q36-P36)+(Q37-P37) -> 0 | R38: =(S36-R36)+(S37-R37) -> 0 | T38: =(U36-T36)+(U37-T37) -> 0 | V38: =(W36-V36)+(W37-V37) -> 0 | X38: =(Y36-X36)+(Y37-X37) -> 0 | Z38: =(AA36-Z36)+(AA37-Z37) -> 0 | AB38: =(AC36-AB36)+(AC37-AB37) -> 0 | AD38: =(AE36-AD36)+(AE37-AD37) -> 0 | AF38: =(AG36-AF36)+(AG37-AF37) -> 0 | AH38: =(AI36-AH36)+(AI37-AH37) -> 0 | AJ38: =(AK36-AJ36)+(AK37-AJ37) -> 0 | AL38: =(AM36-AL36)+(AM37-AL37) -> 0 | AN38: =(AO36-AN36)+(AO37-AN37) -> 0 | AP38: =(AQ36-AP36)+(AQ37-AP37) -> 0 | AR38: =(AS36-AR36)+(AS37-AR37) -> 0 | AT38: =(AU36-AT36)+(AU37-AT37) -> 0 | AV38: =(AW36-AV36)+(AW37-AV37) -> 0 | AX38: =(AY36-AX36)+(AY37-AX37) -> 0 | AZ38: =(BA36-AZ36)+(BA37-AZ37) -> 0 | BB38: =(BC36-BB36)+(BC37-BB37) -> 0 | BD38: =(BE36-BD36)+(BE37-BD37) -> 0 | BF38: =(BG36-BF36)+(BG37-BF37) -> 0 | BH38: =(BI36-BH36)+(BI37-BH37) -> 0 | BJ38: =(BK36-BJ36)+(BK37-BJ37) -> 0 | BL38: =(BM36-BL36)+(BM37-BL37) -> 0 | BN38: =SUM(D38:BM38) -> 0
BN40: =BN41-$BN$5 -> -112
D41: =(E39-D39)+(E40-D40) -> 0 | F41: =(G39-F39)+(G40-F40) -> 0 | H41: =(I39-H39)+(I40-H40) -> 0 | J41: =(K39-J39)+(K40-J40) -> 0 | L41: =(M39-L39)+(M40-L40) -> 0 | N41: =(O39-N39)+(O40-N40) -> 0 | P41: =(Q39-P39)+(Q40-P40) -> 0 | R41: =(S39-R39)+(S40-R40) -> 0 | T41: =(U39-T39)+(U40-T40) -> 0 | V41: =(W39-V39)+(W40-V40) -> 0 | X41: =(Y39-X39)+(Y40-X40) -> 0 | Z41: =(AA39-Z39)+(AA40-Z40) -> 0 | AB41: =(AC39-AB39)+(AC40-AB40) -> 0 | AD41: =(AE39-AD39)+(AE40-AD40) -> 0 | AF41: =(AG39-AF39)+(AG40-AF40) -> 0 | AH41: =(AI39-AH39)+(AI40-AH40) -> 0 | AJ41: =(AK39-AJ39)+(AK40-AJ40) -> 0 | AL41: =(AM39-AL39)+(AM40-AL40) -> 0 | AN41: =(AO39-AN39)+(AO40-AN40) -> 0 | AP41: =(AQ39-AP39)+(AQ40-AP40) -> 0 | AR41: =(AS39-AR39)+(AS40-AR40) -> 0 | AT41: =(AU39-AT39)+(AU40-AT40) -> 0 | AV41: =(AW39-AV39)+(AW40-AV40) -> 0 | AX41: =(AY39-AX39)+(AY40-AX40) -> 0 | AZ41: =(BA39-AZ39)+(BA40-AZ40) -> 0 | BB41: =(BC39-BB39)+(BC40-BB40) -> 0 | BD41: =(BE39-BD39)+(BE40-BD40) -> 0 | BF41: =(BG39-BF39)+(BG40-BF40) -> 0 | BH41: =(BI39-BH39)+(BI40-BH40) -> 0 | BJ41: =(BK39-BJ39)+(BK40-BJ40) -> 0 | BL41: =(BM39-BL39)+(BM40-BL40) -> 0 | BN41: =SUM(D41:BM41) -> 0
B42: 梁芷瑄 | D42: 9 | E42: 13
D43: 14 | E43: 18 | BN43: =BN44-$BN$5 -> -104
D44: =(E42-D42)+(E43-D43) -> 8 | F44: =(G42-F42)+(G43-F43) -> 0 | H44: =(I42-H42)+(I43-H43) -> 0 | J44: =(K42-J42)+(K43-J43) -> 0 | L44: =(M42-L42)+(M43-L43) -> 0 | N44: =(O42-N42)+(O43-N43) -> 0 | P44: =(Q42-P42)+(Q43-P43) -> 0 | R44: =(S42-R42)+(S43-R43) -> 0 | T44: =(U42-T42)+(U43-T43) -> 0 | V44: =(W42-V42)+(W43-V43) -> 0 | X44: =(Y42-X42)+(Y43-X43) -> 0 | Z44: =(AA42-Z42)+(AA43-Z43) -> 0 | AB44: =(AC42-AB42)+(AC43-AB43) -> 0 | AD44: =(AE42-AD42)+(AE43-AD43) -> 0 | AF44: =(AG42-AF42)+(AG43-AF43) -> 0 | AH44: =(AI42-AH42)+(AI43-AH43) -> 0 | AJ44: =(AK42-AJ42)+(AK43-AJ43) -> 0 | AL44: =(AM42-AL42)+(AM43-AL43) -> 0 | AN44: =(AO42-AN42)+(AO43-AN43) -> 0 | AP44: =(AQ42-AP42)+(AQ43-AP43) -> 0 | AR44: =(AS42-AR42)+(AS43-AR43) -> 0 | AT44: =(AU42-AT42)+(AU43-AT43) -> 0 | AV44: =(AW42-AV42)+(AW43-AV43) -> 0 | AX44: =(AY42-AX42)+(AY43-AX43) -> 0 | AZ44: =(BA42-AZ42)+(BA43-AZ43) -> 0 | BB44: =(BC42-BB42)+(BC43-BB43) -> 0 | BD44: =(BE42-BD42)+(BE43-BD43) -> 0 | BF44: =(BG42-BF42)+(BG43-BF43) -> 0 | BH44: =(BI42-BH42)+(BI43-BH43) -> 0 | BJ44: =(BK42-BJ42)+(BK43-BJ43) -> 0 | BL44: =(BM42-BL42)+(BM43-BL43) -> 0 | BN44: =SUM(D44:BM44) -> 8
A45: 中午餐期上班人數 | D45: =COUNTIF(D6:D44,"12")+COUNTIF(D6:D44,"10")+COUNTIF(D6:D44,"11")+COUNTIF(D6:D44,"11.5")+COUNTIF(D6:D44,"10.5") -> 0 | F45: =COUNTIF(F6:F44,"12")+COUNTIF(F6:F44,"10")+COUNTIF(F6:F44,"11")+COUNTIF(F6:F44,"11.5")+COUNTIF(F6:F44,"10.5") -> 0 | H45: =COUNTIF(H6:H44,"12")+COUNTIF(H6:H44,"10")+COUNTIF(H6:H44,"11")+COUNTIF(H6:H44,"11.5")+COUNTIF(H6:H44,"10.5") -> 0 | J45: =COUNTIF(J6:J44,"12")+COUNTIF(J6:J44,"10")+COUNTIF(J6:J44,"11")+COUNTIF(J6:J44,"11.5")+COUNTIF(J6:J44,"10.5") -> 0 | L45: =COUNTIF(L6:L44,"12")+COUNTIF(L6:L44,"10")+COUNTIF(L6:L44,"11")+COUNTIF(L6:L44,"11.5")+COUNTIF(L6:L44,"10.5") -> 0 | N45: =COUNTIF(N6:N44,"12")+COUNTIF(N6:N44,"10")+COUNTIF(N6:N44,"11")+COUNTIF(N6:N44,"11.5")+COUNTIF(N6:N44,"10.5") -> 0 | P45: =COUNTIF(P6:P44,"12")+COUNTIF(P6:P44,"10")+COUNTIF(P6:P44,"11")+COUNTIF(P6:P44,"11.5")+COUNTIF(P6:P44,"10.5") -> 0 | R45: =COUNTIF(R6:R44,"12")+COUNTIF(R6:R44,"10")+COUNTIF(R6:R44,"11")+COUNTIF(R6:R44,"11.5")+COUNTIF(R6:R44,"10.5") -> 0 | T45: =COUNTIF(T6:T44,"12")+COUNTIF(T6:T44,"10")+COUNTIF(T6:T44,"11")+COUNTIF(T6:T44,"11.5")+COUNTIF(T6:T44,"10.5") -> 0 | V45: =COUNTIF(V6:V44,"12")+COUNTIF(V6:V44,"10")+COUNTIF(V6:V44,"11")+COUNTIF(V6:V44,"11.5")+COUNTIF(V6:V44,"10.5") -> 0 | X45: =COUNTIF(X6:X44,"12")+COUNTIF(X6:X44,"10")+COUNTIF(X6:X44,"11")+COUNTIF(X6:X44,"11.5")+COUNTIF(X6:X44,"10.5") -> 0 | Z45: =COUNTIF(Z6:Z44,"12")+COUNTIF(Z6:Z44,"10")+COUNTIF(Z6:Z44,"11")+COUNTIF(Z6:Z44,"11.5")+COUNTIF(Z6:Z44,"10.5") -> 0 | AB45: =COUNTIF(AB6:AB44,"12")+COUNTIF(AB6:AB44,"10")+COUNTIF(AB6:AB44,"11")+COUNTIF(AB6:AB44,"11.5")+COUNTIF(AB6:AB44,"10.5") -> 0 | AD45: =COUNTIF(AD6:AD44,"12")+COUNTIF(AD6:AD44,"10")+COUNTIF(AD6:AD44,"11")+COUNTIF(AD6:AD44,"11.5")+COUNTIF(AD6:AD44,"10.5") -> 0 | AF45: =COUNTIF(AF6:AF44,"12")+COUNTIF(AF6:AF44,"10")+COUNTIF(AF6:AF44,"11")+COUNTIF(AF6:AF44,"11.5")+COUNTIF(AF6:AF44,"10.5") -> 0 | AH45: =COUNTIF(AH6:AH44,"12")+COUNTIF(AH6:AH44,"10")+COUNTIF(AH6:AH44,"11")+COUNTIF(AH6:AH44,"11.5")+COUNTIF(AH6:AH44,"10.5") -> 0 | AJ45: =COUNTIF(AJ6:AJ44,"12")+COUNTIF(AJ6:AJ44,"10")+COUNTIF(AJ6:AJ44,"11")+COUNTIF(AJ6:AJ44,"11.5")+COUNTIF(AJ6:AJ44,"10.5") -> 0 | AL45: =COUNTIF(AL6:AL44,"12")+COUNTIF(AL6:AL44,"10")+COUNTIF(AL6:AL44,"11")+COUNTIF(AL6:AL44,"11.5")+COUNTIF(AL6:AL44,"10.5") -> 0 | AN45: =COUNTIF(AN6:AN44,"12")+COUNTIF(AN6:AN44,"10")+COUNTIF(AN6:AN44,"11")+COUNTIF(AN6:AN44,"11.5")+COUNTIF(AN6:AN44,"10.5") -> 0 | AP45: =COUNTIF(AP6:AP44,"12")+COUNTIF(AP6:AP44,"10")+COUNTIF(AP6:AP44,"11")+COUNTIF(AP6:AP44,"11.5")+COUNTIF(AP6:AP44,"10.5") -> 0 | AR45: =COUNTIF(AR6:AR44,"12")+COUNTIF(AR6:AR44,"10")+COUNTIF(AR6:AR44,"11")+COUNTIF(AR6:AR44,"11.5")+COUNTIF(AR6:AR44,"10.5") -> 0 | AT45: =COUNTIF(AT6:AT44,"12")+COUNTIF(AT6:AT44,"10")+COUNTIF(AT6:AT44,"11")+COUNTIF(AT6:AT44,"11.5")+COUNTIF(AT6:AT44,"10.5") -> 0 | AV45: =COUNTIF(AV6:AV44,"12")+COUNTIF(AV6:AV44,"10")+COUNTIF(AV6:AV44,"11")+COUNTIF(AV6:AV44,"11.5")+COUNTIF(AV6:AV44,"10.5") -> 0 | AX45: =COUNTIF(AX6:AX44,"12")+COUNTIF(AX6:AX44,"10")+COUNTIF(AX6:AX44,"11")+COUNTIF(AX6:AX44,"11.5")+COUNTIF(AX6:AX44,"10.5") -> 0 | AZ45: =COUNTIF(AZ6:AZ44,"12")+COUNTIF(AZ6:AZ44,"10")+COUNTIF(AZ6:AZ44,"11")+COUNTIF(AZ6:AZ44,"11.5")+COUNTIF(AZ6:AZ44,"10.5") -> 0 | BB45: =COUNTIF(BB6:BB44,"12")+COUNTIF(BB6:BB44,"10")+COUNTIF(BB6:BB44,"11")+COUNTIF(BB6:BB44,"11.5")+COUNTIF(BB6:BB44,"10.5") -> 0 | BD45: =COUNTIF(BD6:BD44,"12")+COUNTIF(BD6:BD44,"10")+COUNTIF(BD6:BD44,"11")+COUNTIF(BD6:BD44,"11.5")+COUNTIF(BD6:BD44,"10.5") -> 0 | BF45: =COUNTIF(BF6:BF44,"12")+COUNTIF(BF6:BF44,"10")+COUNTIF(BF6:BF44,"11")+COUNTIF(BF6:BF44,"11.5")+COUNTIF(BF6:BF44,"10.5") -> 0 | BH45: =COUNTIF(BH6:BH44,"12")+COUNTIF(BH6:BH44,"10")+COUNTIF(BH6:BH44,"11")+COUNTIF(BH6:BH44,"11.5")+COUNTIF(BH6:BH44,"10.5") -> 0 | BJ45: =COUNTIF(BJ6:BJ44,"12")+COUNTIF(BJ6:BJ44,"10")+COUNTIF(BJ6:BJ44,"11")+COUNTIF(BJ6:BJ44,"11.5")+COUNTIF(BJ6:BJ44,"10.5") -> 0 | BL45: =COUNTIF(BL6:BL44,"12")+COUNTIF(BL6:BL44,"10")+COUNTIF(BL6:BL44,"11")+COUNTIF(BL6:BL44,"11.5")+COUNTIF(BL6:BL44,"10.5") -> 0 | BN45: 總時數
A46: 下午餐期上班人數 | D46: =COUNTIF(E3:E44,"16")+COUNTIF(E3:E44,"16.5")+COUNTIF(E3:E44,"17") -> 0 | F46: =COUNTIF(G3:G44,"16")+COUNTIF(G3:G44,"16.5")+COUNTIF(G3:G44,"17") -> 0 | H46: =COUNTIF(I3:I44,"16")+COUNTIF(I3:I44,"16.5")+COUNTIF(I3:I44,"17") -> 0 | J46: =COUNTIF(K3:K44,"16")+COUNTIF(K3:K44,"16.5")+COUNTIF(K3:K44,"17") -> 0 | L46: =COUNTIF(M3:M44,"16")+COUNTIF(M3:M44,"16.5")+COUNTIF(M3:M44,"17") -> 0 | N46: =COUNTIF(O3:O44,"16")+COUNTIF(O3:O44,"16.5")+COUNTIF(O3:O44,"17") -> 0 | P46: =COUNTIF(Q3:Q44,"16")+COUNTIF(Q3:Q44,"16.5")+COUNTIF(Q3:Q44,"17") -> 0 | R46: =COUNTIF(S3:S44,"16")+COUNTIF(S3:S44,"16.5")+COUNTIF(S3:S44,"17") -> 0 | T46: =COUNTIF(U3:U44,"16")+COUNTIF(U3:U44,"16.5")+COUNTIF(U3:U44,"17") -> 0 | V46: =COUNTIF(W3:W44,"16")+COUNTIF(W3:W44,"16.5")+COUNTIF(W3:W44,"17") -> 0 | X46: =COUNTIF(Y3:Y44,"16")+COUNTIF(Y3:Y44,"16.5")+COUNTIF(Y3:Y44,"17") -> 0 | Z46: =COUNTIF(AA3:AA44,"16")+COUNTIF(AA3:AA44,"16.5")+COUNTIF(AA3:AA44,"17") -> 0 | AB46: =COUNTIF(AC3:AC44,"16")+COUNTIF(AC3:AC44,"16.5")+COUNTIF(AC3:AC44,"17") -> 0 | AD46: =COUNTIF(AE3:AE44,"16")+COUNTIF(AE3:AE44,"16.5")+COUNTIF(AE3:AE44,"17") -> 0 | AF46: =COUNTIF(AG3:AG44,"16")+COUNTIF(AG3:AG44,"16.5")+COUNTIF(AG3:AG44,"17") -> 0 | AH46: =COUNTIF(AI3:AI44,"16")+COUNTIF(AI3:AI44,"16.5")+COUNTIF(AI3:AI44,"17") -> 0 | AJ46: =COUNTIF(AK3:AK44,"16")+COUNTIF(AK3:AK44,"16.5")+COUNTIF(AK3:AK44,"17") -> 0 | AL46: =COUNTIF(AM3:AM44,"16")+COUNTIF(AM3:AM44,"16.5")+COUNTIF(AM3:AM44,"17") -> 0 | AN46: =COUNTIF(AO3:AO44,"16")+COUNTIF(AO3:AO44,"16.5")+COUNTIF(AO3:AO44,"17") -> 0 | AP46: =COUNTIF(AQ3:AQ44,"16")+COUNTIF(AQ3:AQ44,"16.5")+COUNTIF(AQ3:AQ44,"17") -> 0 | AR46: =COUNTIF(AS3:AS44,"16")+COUNTIF(AS3:AS44,"16.5")+COUNTIF(AS3:AS44,"17") -> 0 | AT46: =COUNTIF(AU3:AU44,"16")+COUNTIF(AU3:AU44,"16.5")+COUNTIF(AU3:AU44,"17") -> 0 | AV46: =COUNTIF(AW3:AW44,"16")+COUNTIF(AW3:AW44,"16.5")+COUNTIF(AW3:AW44,"17") -> 0 | AX46: =COUNTIF(AY3:AY44,"16")+COUNTIF(AY3:AY44,"16.5")+COUNTIF(AY3:AY44,"17") -> 0 | AZ46: =COUNTIF(BA3:BA44,"16")+COUNTIF(BA3:BA44,"16.5")+COUNTIF(BA3:BA44,"17") -> 0 | BB46: =COUNTIF(BC3:BC44,"16")+COUNTIF(BC3:BC44,"16.5")+COUNTIF(BC3:BC44,"17") -> 0 | BD46: =COUNTIF(BE3:BE44,"16")+COUNTIF(BE3:BE44,"16.5")+COUNTIF(BE3:BE44,"17") -> 0 | BF46: =COUNTIF(BG3:BG44,"16")+COUNTIF(BG3:BG44,"16.5")+COUNTIF(BG3:BG44,"17") -> 0 | BH46: =COUNTIF(BI3:BI44,"16")+COUNTIF(BI3:BI44,"16.5")+COUNTIF(BI3:BI44,"17") -> 0 | BJ46: =COUNTIF(BK3:BK44,"16")+COUNTIF(BK3:BK44,"16.5")+COUNTIF(BK3:BK44,"17") -> 0 | BL46: =COUNTIF(BM3:BM44,"16")+COUNTIF(BM3:BM44,"16.5")+COUNTIF(BM3:BM44,"17") -> 0
...

Sheet 外場轉化
A1: 本列維持與前頁格式一致，請勿刪除
A4: =整月外場班表!A4 -> 白霧時光 板橋傑仕堡 | D4: =整月外場班表!D4 -> 46204 | F4: =D4+1 -> 46205 | H4: =F4+1 -> 46206 | J4: =H4+1 -> 46207 | L4: =J4+1 -> 46208 | N4: =L4+1 -> 46209 | P4: =N4+1 -> 46210 | R4: =P4+1 -> 46211 | T4: =R4+1 -> 46212 | V4: =T4+1 -> 46213 | X4: =V4+1 -> 46214 | Z4: =X4+1 -> 46215 | AB4: =Z4+1 -> 46216 | AD4: =AB4+1 -> 46217 | AF4: =AD4+1 -> 46218 | AH4: =AF4+1 -> 46219 | AJ4: =AH4+1 -> 46220 | AL4: =AJ4+1 -> 46221 | AN4: =AL4+1 -> 46222 | AP4: =AN4+1 -> 46223 | AR4: =AP4+1 -> 46224 | AT4: =AR4+1 -> 46225 | AV4: =AT4+1 -> 46226 | AX4: =AV4+1 -> 46227 | AZ4: =AX4+1 -> 46228 | BB4: =AZ4+1 -> 46229 | BD4: =BB4+1 -> 46230 | BF4: =BD4+1 -> 46231 | BH4: =BF4+1 -> 46232 | BJ4: =BH4+1 -> 46233
D5: 週六 | F5: 週日 | H5: 週一 | J5: 週二 | L5: 週三 | N5: 週四 | P5: 週五 | R5: 週六 | T5: 週日 | V5: 週一 | X5: 週二 | Z5: 週三 | AB5: 週四 | AD5: 週五 | AF5: 週六 | AH5: 週日 | AJ5: 週一 | AL5: 週二 | AN5: 週三 | AP5: 週四 | AR5: 週五 | AT5: 週六 | AV5: 週日 | AX5: 週一 | AZ5: 週二 | BB5: 週三 | BD5: 週四 | BF5: 週五 | BH5: 週六 | BJ5: 週日
B6: =整月外場班表!B6 -> 張意昕 | D6: =IF(MOD(整月外場班表!D6,1)=0,CONCATENATE(整月外場班表!D6,"00"),CONCATENATE(INT(整月外場班表!D6),"30")) -> 00 | E6: =IF(MOD(整月外場班表!E6,1)=0,CONCATENATE(整月外場班表!E6,"00"),CONCATENATE(INT(整月外場班表!E6),"30")) -> 00 | F6: =IF(MOD(整月外場班表!F6,1)=0,CONCATENATE(整月外場班表!F6,"00"),CONCATENATE(INT(整月外場班表!F6),"30")) -> 00 | G6: =IF(MOD(整月外場班表!G6,1)=0,CONCATENATE(整月外場班表!G6,"00"),CONCATENATE(INT(整月外場班表!G6),"30")) -> 00 | H6: =IF(MOD(整月外場班表!H6,1)=0,CONCATENATE(整月外場班表!H6,"00"),CONCATENATE(INT(整月外場班表!H6),"30")) -> 00 | I6: =IF(MOD(整月外場班表!I6,1)=0,CONCATENATE(整月外場班表!I6,"00"),CONCATENATE(INT(整月外場班表!I6),"30")) -> 00 | J6: =IF(MOD(整月外場班表!J6,1)=0,CONCATENATE(整月外場班表!J6,"00"),CONCATENATE(INT(整月外場班表!J6),"30")) -> 00 | K6: =IF(MOD(整月外場班表!K6,1)=0,CONCATENATE(整月外場班表!K6,"00"),CONCATENATE(INT(整月外場班表!K6),"30")) -> 00 | ... BM6: =IF(MOD(整月外場班表!BM6,1)=0,CONCATENATE(整月外場班表!BM6,"00"),CONCATENATE(INT(整月外場班表!BM6),"30")) -> 00
D7: =IF(MOD(整月外場班表!D7,1)=0,CONCATENATE(整月外場班表!D7,"00"),CONCATENATE(INT(整月外場班表!D7),"30")) -> 00 | E7: =IF(MOD(整月外場班表!E7,1)=0,CONCATENATE(整月外場班表!E7,"00"),CONCATENATE(INT(整月外場班表!E7),"30")) -> 00 | F7: =IF(MOD(整月外場班表!F7,1)=0,CONCATENATE(整月外場班表!F7,"00"),CONCATENATE(INT(整月外場班表!F7),"30")) -> 00 | G7: =IF(MOD(整月外場班表!G7,1)=0,CONCATENATE(整月外場班表!G7,"00"),CONCATENATE(INT(整月外場班表!G7),"30")) -> 00 | H7: =IF(MOD(整月外場班表!H7,1)=0,CONCATENATE(整月外場班表!H7,"00"),CONCATENATE(INT(整月外場班表!H7),"30")) -> 00 | I7: =IF(MOD(整月外場班表!I7,1)=0,CONCATENATE(整月外場班表!I7,"00"),CONCATENATE(INT(整月外場班表!I7),"30")) -> 00 | J7: =IF(MOD(整月外場班表!J7,1)=0,CONCATENATE(整月外場班表!J7,"00"),CONCATENATE(INT(整月外場班表!J7),"30")) -> 00 | K7: =IF(MOD(整月外場班表!K7,1)=0,CONCATENATE(整月外場班表!K7,"00"),CONCATENATE(INT(整月外場班表!K7),"30")) -> 00 | ... BM7: =IF(MOD(整月外場班表!BM7,1)=0,CONCATENATE(整月外場班表!BM7,"00"),CONCATENATE(INT(整月外場班表!BM7),"30")) -> 00
D8: {=_xlfn.IFS(AND(D6="00",D7="00"),";H",AND(D6<>"00",D7<>"00"),CONCATENATE(D6,"-",E7,"(",E6,"-",D7,")"),AND(D6="00",D7<>"00"),CONCATENATE(D7,"-",E7),AND(D6<>"00",D7="00"),CONCATENATE(D6,"-",E6))} -> ;H | F8: {=_xlfn.IFS(AND(F6="00",F7="00"),";H",AND(F6<>"00",F7<>"00"),CONCATENATE(F6,"-",G7,"(",G6,"-",F7,")"),AND(F6="00",F7<>"00"),CONCATENATE(F7,"-",G7),AND(F6<>"00",F7="00"),CONCATENATE(F6,"-",G6))} -> ;H | H8: {=_xlfn.IFS(AND(H6="00",H7="00"),";H",AND(H6<>"00",H7<>"00"),CONCATENATE(H6,"-",I7,"(",I6,"-",H7,")"),AND(H6="00",H7<>"00"),CONCATENATE(H7,"-",I7),AND(H6<>"00",H7="00"),CONCATENATE(H6,"-",I6))} -> ;H | J8: {=_xlfn.IFS(AND(J6="00",J7="00"),";H",AND(J6<>"00",J7<>"00"),CONCATENATE(J6,"-",K7,"(",K6,"-",J7,")"),AND(J6="00",J7<>"00"),CONCATENATE(J7,"-",K7),AND(J6<>"00",J7="00"),CONCATENATE(J6,"-",K6))} -> ;H | L8: {=_xlfn.IFS(AND(L6="00",L7="00"),";H",AND(L6<>"00",L7<>"00"),CONCATENATE(L6,"-",M7,"(",M6,"-",L7,")"),AND(L6="00",L7<>"00"),CONCATENATE(L7,"-",M7),AND(L6<>"00",L7="00"),CONCATENATE(L6,"-",M6))} -> ;H | N8: {=_xlfn.IFS(AND(N6="00",N7="00"),";H",AND(N6<>"00",N7<>"00"),CONCATENATE(N6,"-",O7,"(",O6,"-",N7,")"),AND(N6="00",N7<>"00"),CONCATENATE(N7,"-",O7),AND(N6<>"00",N7="00"),CONCATENATE(N6,"-",O6))} -> ;H | P8: {=_xlfn.IFS(AND(P6="00",P7="00"),";H",AND(P6<>"00",P7<>"00"),CONCATENATE(P6,"-",Q7,"(",Q6,"-",P7,")"),AND(P6="00",P7<>"00"),CONCATENATE(P7,"-",Q7),AND(P6<>"00",P7="00"),CONCATENATE(P6,"-",Q6))} -> ;H | R8: {=_xlfn.IFS(AND(R6="00",R7="00"),";H",AND(R6<>"00",R7<>"00"),CONCATENATE(R6,"-",S7,"(",S6,"-",R7,")"),AND(R6="00",R7<>"00"),CONCATENATE(R7,"-",S7),AND(R6<>"00",R7="00"),CONCATENATE(R6,"-",S6))} -> ;H | T8: {=_xlfn.IFS(AND(T6="00",T7="00"),";H",AND(T6<>"00",T7<>"00"),CONCATENATE(T6,"-",U7,"(",U6,"-",T7,")"),AND(T6="00",T7<>"00"),CONCATENATE(T7,"-",U7),AND(T6<>"00",T7="00"),CONCATENATE(T6,"-",U6))} -> ;H | V8: {=_xlfn.IFS(AND(V6="00",V7="00"),";H",AND(V6<>"00",V7<>"00"),CONCATENATE(V6,"-",W7,"(",W6,"-",V7,")"),AND(V6="00",V7<>"00"),CONCATENATE(V7,"-",W7),AND(V6<>"00",V7="00"),CONCATENATE(V6,"-",W6))} -> ;H | X8: {=_xlfn.IFS(AND(X6="00",X7="00"),";H",AND(X6<>"00",X7<>"00"),CONCATENATE(X6,"-",Y7,"(",Y6,"-",X7,")"),AND(X6="00",X7<>"00"),CONCATENATE(X7,"-",Y7),AND(X6<>"00",X7="00"),CONCATENATE(X6,"-",Y6))} -> ;H | Z8: {=_xlfn.IFS(AND(Z6="00",Z7="00"),";H",AND(Z6<>"00",Z7<>"00"),CONCATENATE(Z6,"-",AA7,"(",AA6,"-",Z7,")"),AND(Z6="00",Z7<>"00"),CONCATENATE(Z7,"-",AA7),AND(Z6<>"00",Z7="00"),CONCATENATE(Z6,"-",AA6))} -> ;H | AB8: {=_xlfn.IFS(AND(AB6="00",AB7="00"),";H",AND(AB6<>"00",AB7<>"00"),CONCATENATE(AB6,"-",AC7,"(",AC6,"-",AB7,")"),AND(AB6="00",AB7<>"00"),CONCATENATE(AB7,"-",AC7),AND(AB6<>"00",AB7="00"),CONCATENATE(AB6,"-",AC6))} -> ;H | AD8: {=_xlfn.IFS(AND(AD6="00",AD7="00"),";H",AND(AD6<>"00",AD7<>"00"),CONCATENATE(AD6,"-",AE7,"(",AE6,"-",AD7,")"),AND(AD6="00",AD7<>"00"),CONCATENATE(AD7,"-",AE7),AND(AD6<>"00",AD7="00"),CONCATENATE(AD6,"-",AE6))} -> ;H | AF8: {=_xlfn.IFS(AND(AF6="00",AF7="00"),";H",AND(AF6<>"00",AF7<>"00"),CONCATENATE(AF6,"-",AG7,"(",AG6,"-",AF7,")"),AND(AF6="00",AF7<>"00"),CONCATENATE(AF7,"-",AG7),AND(AF6<>"00",AF7="00"),CONCATENATE(AF6,"-",AG6))} -> ;H | AH8: {=_xlfn.IFS(AND(AH6="00",AH7="00"),";H",AND(AH6<>"00",AH7<>"00"),CONCATENATE(AH6,"-",AI7,"(",AI6,"-",AH7,")"),AND(AH6="00",AH7<>"00"),CONCATENATE(AH7,"-",AI7),AND(AH6<>"00",AH7="00"),CONCATENATE(AH6,"-",AI6))} -> ;H | AJ8: {=_xlfn.IFS(AND(AJ6="00",AJ7="00"),";H",AND(AJ6<>"00",AJ7<>"00"),CONCATENATE(AJ6,"-",AK7,"(",AK6,"-",AJ7,")"),AND(AJ6="00",AJ7<>"00"),CONCATENATE(AJ7,"-",AK7),AND(AJ6<>"00",AJ7="00"),CONCATENATE(AJ6,"-",AK6))} -> ;H | AL8: {=_xlfn.IFS(AND(AL6="00",AL7="00"),";H",AND(AL6<>"00",AL7<>"00"),CONCATENATE(AL6,"-",AM7,"(",AM6,"-",AL7,")"),AND(AL6="00",AL7<>"00"),CONCATENATE(AL7,"-",AM7),AND(AL6<>"00",AL7="00"),CONCATENATE(AL6,"-",AM6))} -> ;H | AN8: {=_xlfn.IFS(AND(AN6="00",AN7="00"),";H",AND(AN6<>"00",AN7<>"00"),CONCATENATE(AN6,"-",AO7,"(",AO6,"-",AN7,")"),AND(AN6="00",AN7<>"00"),CONCATENATE(AN7,"-",AO7),AND(AN6<>"00",AN7="00"),CONCATENATE(AN6,"-",AO6))} -> ;H | AP8: {=_xlfn.IFS(AND(AP6="00",AP7="00"),";H",AND(AP6<>"00",AP7<>"00"),CONCATENATE(AP6,"-",AQ7,"(",AQ6,"-",AP7,")"),AND(AP6="00",AP7<>"00"),CONCATENATE(AP7,"-",AQ7),AND(AP6<>"00",AP7="00"),CONCATENATE(AP6,"-",AQ6))} -> ;H | AR8: {=_xlfn.IFS(AND(AR6="00",AR7="00"),";H",AND(AR6<>"00",AR7<>"00"),CONCATENATE(AR6,"-",AS7,"(",AS6,"-",AR7,")"),AND(AR6="00",AR7<>"00"),CONCATENATE(AR7,"-",AS7),AND(AR6<>"00",AR7="00"),CONCATENATE(AR6,"-",AS6))} -> ;H | AT8: {=_xlfn.IFS(AND(AT6="00",AT7="00"),";H",AND(AT6<>"00",AT7<>"00"),CONCATENATE(AT6,"-",AU7,"(",AU6,"-",AT7,")"),AND(AT6="00",AT7<>"00"),CONCATENATE(AT7,"-",AU7),AND(AT6<>"00",AT7="00"),CONCATENATE(AT6,"-",AU6))} -> ;H | AV8: {=_xlfn.IFS(AND(AV6="00",AV7="00"),";H",AND(AV6<>"00",AV7<>"00"),CONCATENATE(AV6,"-",AW7,"(",AW6,"-",AV7,")"),AND(AV6="00",AV7<>"00"),CONCATENATE(AV7,"-",AW7),AND(AV6<>"00",AV7="00"),CONCATENATE(AV6,"-",AW6))} -> ;H | AX8: {=_xlfn.IFS(AND(AX6="00",AX7="00"),";H",AND(AX6<>"00",AX7<>"00"),CONCATENATE(AX6,"-",AY7,"(",AY6,"-",AX7,")"),AND(AX6="00",AX7<>"00"),CONCATENATE(AX7,"-",AY7),AND(AX6<>"00",AX7="00"),CONCATENATE(AX6,"-",AY6))} -> ;H | AZ8: {=_xlfn.IFS(AND(AZ6="00",AZ7="00"),";H",AND(AZ6<>"00",AZ7<>"00"),CONCATENATE(AZ6,"-",BA7,"(",BA6,"-",AZ7,")"),AND(AZ6="00",AZ7<>"00"),CONCATENATE(AZ7,"-",BA7),AND(AZ6<>"00",AZ7="00"),CONCATENATE(AZ6,"-",BA6))} -> ;H | BB8: {=_xlfn.IFS(AND(BB6="00",BB7="00"),";H",AND(BB6<>"00",BB7<>"00"),CONCATENATE(BB6,"-",BC7,"(",BC6,"-",BB7,")"),AND(BB6="00",BB7<>"00"),CONCATENATE(BB7,"-",BC7),AND(BB6<>"00",BB7="00"),CONCATENATE(BB6,"-",BC6))} -> ;H | BD8: {=_xlfn.IFS(AND(BD6="00",BD7="00"),";H",AND(BD6<>"00",BD7<>"00"),CONCATENATE(BD6,"-",BE7,"(",BE6,"-",BD7,")"),AND(BD6="00",BD7<>"00"),CONCATENATE(BD7,"-",BE7),AND(BD6<>"00",BD7="00"),CONCATENATE(BD6,"-",BE6))} -> ;H | BF8: {=_xlfn.IFS(AND(BF6="00",BF7="00"),";H",AND(BF6<>"00",BF7<>"00"),CONCATENATE(BF6,"-",BG7,"(",BG6,"-",BF7,")"),AND(BF6="00",BF7<>"00"),CONCATENATE(BF7,"-",BG7),AND(BF6<>"00",BF7="00"),CONCATENATE(BF6,"-",BG6))} -> ;H | BH8: {=_xlfn.IFS(AND(BH6="00",BH7="00"),";H",AND(BH6<>"00",BH7<>"00"),CONCATENATE(BH6,"-",BI7,"(",BI6,"-",BH7,")"),AND(BH6="00",BH7<>"00"),CONCATENATE(BH7,"-",BI7),AND(BH6<>"00",BH7="00"),CONCATENATE(BH6,"-",BI6))} -> ;H | BJ8: {=_xlfn.IFS(AND(BJ6="00",BJ7="00"),";H",AND(BJ6<>"00",BJ7<>"00"),CONCATENATE(BJ6,"-",BK7,"(",BK6,"-",BJ7,")"),AND(BJ6="00",BJ7<>"00"),CONCATENATE(BJ7,"-",BK7),AND(BJ6<>"00",BJ7="00"),CONCATENATE(BJ6,"-",BK6))} -> ;H | BL8: {=_xlfn.IFS(AND(BL6="00",BL7="00"),";H",AND(BL6<>"00",BL7<>"00"),CONCATENATE(BL6,"-",BM7,"(",BM6,"-",BL7,")"),AND(BL6="00",BL7<>"00"),CONCATENATE(BL7,"-",BM7),AND(BL6<>"00",BL7="00"),CONCATENATE(BL6,"-",BM6))} -> ;H
B9: =整月外場班表!B9 -> 楊衡欣 | D9: =IF(MOD(整月外場班表!D9,1)=0,CONCATENATE(整月外場班表!D9,"00"),CONCATENATE(INT(整月外場班表!D9),"30")) -> 00 | E9: =IF(MOD(整月外場班表!E9,1)=0,CONCATENATE(整月外場班表!E9,"00"),CONCATENATE(INT(整月外場班表!E9),"30")) -> 00 | F9: =IF(MOD(整月外場班表!F9,1)=0,CONCATENATE(整月外場班表!F9,"00"),CONCATENATE(INT(整月外場班表!F9),"30")) -> 00 | G9: =IF(MOD(整月外場班表!G9,1)=0,CONCATENATE(整月外場班表!G9,"00"),CONCATENATE(INT(整月外場班表!G9),"30")) -> 00 | H9: =IF(MOD(整月外場班表!H9,1)=0,CONCATENATE(整月外場班表!H9,"00"),CONCATENATE(INT(整月外場班表!H9),"30")) -> 00 | I9: =IF(MOD(整月外場班表!I9,1)=0,CONCATENATE(整月外場班表!I9,"00"),CONCATENATE(INT(整月外場班表!I9),"30")) -> 00 | J9: =IF(MOD(整月外場班表!J9,1)=0,CONCATENATE(整月外場班表!J9,"00"),CONCATENATE(INT(整月外場班表!J9),"30")) -> 00 | K9: =IF(MOD(整月外場班表!K9,1)=0,CONCATENATE(整月外場班表!K9,"00"),CONCATENATE(INT(整月外場班表!K9),"30")) -> 00 | ... BM9: =IF(MOD(整月外場班表!BM9,1)=0,CONCATENATE(整月外場班表!BM9,"00"),CONCATENATE(INT(整月外場班表!BM9),"30")) -> 00
D10: =IF(MOD(整月外場班表!D10,1)=0,CONCATENATE(整月外場班表!D10,"00"),CONCATENATE(INT(整月外場班表!D10),"30")) -> 00 | E10: =IF(MOD(整月外場班表!E10,1)=0,CONCATENATE(整月外場班表!E10,"00"),CONCATENATE(INT(整月外場班表!E10),"30")) -> 00 | F10: =IF(MOD(整月外場班表!F10,1)=0,CONCATENATE(整月外場班表!F10,"00"),CONCATENATE(INT(整月外場班表!F10),"30")) -> 00 | G10: =IF(MOD(整月外場班表!G10,1)=0,CONCATENATE(整月外場班表!G10,"00"),CONCATENATE(INT(整月外場班表!G10),"30")) -> 00 | H10: =IF(MOD(整月外場班表!H10,1)=0,CONCATENATE(整月外場班表!H10,"00"),CONCATENATE(INT(整月外場班表!H10),"30")) -> 00 | I10: =IF(MOD(整月外場班表!I10,1)=0,CONCATENATE(整月外場班表!I10,"00"),CONCATENATE(INT(整月外場班表!I10),"30")) -> 00 | J10: =IF(MOD(整月外場班表!J10,1)=0,CONCATENATE(整月外場班表!J10,"00"),CONCATENATE(INT(整月外場班表!J10),"30")) -> 00 | K10: =IF(MOD(整月外場班表!K10,1)=0,CONCATENATE(整月外場班表!K10,"00"),CONCATENATE(INT(整月外場班表!K10),"30")) -> 00 | ... BM10: =IF(MOD(整月外場班表!BM10,1)=0,CONCATENATE(整月外場班表!BM10,"00"),CONCATENATE(INT(整月外場班表!BM10),"30")) -> 00
D11: {=_xlfn.IFS(AND(D9="00",D10="00"),";H",AND(D9<>"00",D10<>"00"),CONCATENATE(D9,"-",E10,"(",E9,"-",D10,")"),AND(D9="00",D10<>"00"),CONCATENATE(D10,"-",E10),AND(D9<>"00",D10="00"),CONCATENATE(D9,"-",E9))} -> ;H | F11: {=_xlfn.IFS(AND(F9="00",F10="00"),";H",AND(F9<>"00",F10<>"00"),CONCATENATE(F9,"-",G10,"(",G9,"-",F10,")"),AND(F9="00",F10<>"00"),CONCATENATE(F10,"-",G10),AND(F9<>"00",F10="00"),CONCATENATE(F9,"-",G9))} -> ;H | H11: {=_xlfn.IFS(AND(H9="00",H10="00"),";H",AND(H9<>"00",H10<>"00"),CONCATENATE(H9,"-",I10,"(",I9,"-",H10,")"),AND(H9="00",H10<>"00"),CONCATENATE(H10,"-",I10),AND(H9<>"00",H10="00"),CONCATENATE(H9,"-",I9))} -> ;H | J11: {=_xlfn.IFS(AND(J9="00",J10="00"),";H",AND(J9<>"00",J10<>"00"),CONCATENATE(J9,"-",K10,"(",K9,"-",J10,")"),AND(J9="00",J10<>"00"),CONCATENATE(J10,"-",K10),AND(J9<>"00",J10="00"),CONCATENATE(J9,"-",K9))} -> ;H | L11: {=_xlfn.IFS(AND(L9="00",L10="00"),";H",AND(L9<>"00",L10<>"00"),CONCATENATE(L9,"-",M10,"(",M9,"-",L10,")"),AND(L9="00",L10<>"00"),CONCATENATE(L10,"-",M10),AND(L9<>"00",L10="00"),CONCATENATE(L9,"-",M9))} -> ;H | N11: {=_xlfn.IFS(AND(N9="00",N10="00"),";H",AND(N9<>"00",N10<>"00"),CONCATENATE(N9,"-",O10,"(",O9,"-",N10,")"),AND(N9="00",N10<>"00"),CONCATENATE(N10,"-",O10),AND(N9<>"00",N10="00"),CONCATENATE(N9,"-",O9))} -> ;H | P11: {=_xlfn.IFS(AND(P9="00",P10="00"),";H",AND(P9<>"00",P10<>"00"),CONCATENATE(P9,"-",Q10,"(",Q9,"-",P10,")"),AND(P9="00",P10<>"00"),CONCATENATE(P10,"-",Q10),AND(P9<>"00",P10="00"),CONCATENATE(P9,"-",Q9))} -> ;H | R11: {=_xlfn.IFS(AND(R9="00",R10="00"),";H",AND(R9<>"00",R10<>"00"),CONCATENATE(R9,"-",S10,"(",S9,"-",R10,")"),AND(R9="00",R10<>"00"),CONCATENATE(R10,"-",S10),AND(R9<>"00",R10="00"),CONCATENATE(R9,"-",S9))} -> ;H | T11: {=_xlfn.IFS(AND(T9="00",T10="00"),";H",AND(T9<>"00",T10<>"00"),CONCATENATE(T9,"-",U10,"(",U9,"-",T10,")"),AND(T9="00",T10<>"00"),CONCATENATE(T10,"-",U10),AND(T9<>"00",T10="00"),CONCATENATE(T9,"-",U9))} -> ;H | V11: {=_xlfn.IFS(AND(V9="00",V10="00"),";H",AND(V9<>"00",V10<>"00"),CONCATENATE(V9,"-",W10,"(",W9,"-",V10,")"),AND(V9="00",V10<>"00"),CONCATENATE(V10,"-",W10),AND(V9<>"00",V10="00"),CONCATENATE(V9,"-",W9))} -> ;H | X11: {=_xlfn.IFS(AND(X9="00",X10="00"),";H",AND(X9<>"00",X10<>"00"),CONCATENATE(X9,"-",Y10,"(",Y9,"-",X10,")"),AND(X9="00",X10<>"00"),CONCATENATE(X10,"-",Y10),AND(X9<>"00",X10="00"),CONCATENATE(X9,"-",Y9))} -> ;H | Z11: {=_xlfn.IFS(AND(Z9="00",Z10="00"),";H",AND(Z9<>"00",Z10<>"00"),CONCATENATE(Z9,"-",AA10,"(",AA9,"-",Z10,")"),AND(Z9="00",Z10<>"00"),CONCATENATE(Z10,"-",AA10),AND(Z9<>"00",Z10="00"),CONCATENATE(Z9,"-",AA9))} -> ;H | AB11: {=_xlfn.IFS(AND(AB9="00",AB10="00"),";H",AND(AB9<>"00",AB10<>"00"),CONCATENATE(AB9,"-",AC10,"(",AC9,"-",AB10,")"),AND(AB9="00",AB10<>"00"),CONCATENATE(AB10,"-",AC10),AND(AB9<>"00",AB10="00"),CONCATENATE(AB9,"-",AC9))} -> ;H | AD11: {=_xlfn.IFS(AND(AD9="00",AD10="00"),";H",AND(AD9<>"00",AD10<>"00"),CONCATENATE(AD9,"-",AE10,"(",AE9,"-",AD10,")"),AND(AD9="00",AD10<>"00"),CONCATENATE(AD10,"-",AE10),AND(AD9<>"00",AD10="00"),CONCATENATE(AD9,"-",AE9))} -> ;H | AF11: {=_xlfn.IFS(AND(AF9="00",AF10="00"),";H",AND(AF9<>"00",AF10<>"00"),CONCATENATE(AF9,"-",AG10,"(",AG9,"-",AF10,")"),AND(AF9="00",AF10<>"00"),CONCATENATE(AF10,"-",AG10),AND(AF9<>"00",AF10="00"),CONCATENATE(AF9,"-",AG9))} -> ;H | AH11: {=_xlfn.IFS(AND(AH9="00",AH10="00"),";H",AND(AH9<>"00",AH10<>"00"),CONCATENATE(AH9,"-",AI10,"(",AI9,"-",AH10,")"),AND(AH9="00",AH10<>"00"),CONCATENATE(AH10,"-",AI10),AND(AH9<>"00",AH10="00"),CONCATENATE(AH9,"-",AI9))} -> ;H | AJ11: {=_xlfn.IFS(AND(AJ9="00",AJ10="00"),";H",AND(AJ9<>"00",AJ10<>"00"),CONCATENATE(AJ9,"-",AK10,"(",AK9,"-",AJ10,")"),AND(AJ9="00",AJ10<>"00"),CONCATENATE(AJ10,"-",AK10),AND(AJ9<>"00",AJ10="00"),CONCATENATE(AJ9,"-",AK9))} -> ;H | AL11: {=_xlfn.IFS(AND(AL9="00",AL10="00"),";H",AND(AL9<>"00",AL10<>"00"),CONCATENATE(AL9,"-",AM10,"(",AM9,"-",AL10,")"),AND(AL9="00",AL10<>"00"),CONCATENATE(AL10,"-",AM10),AND(AL9<>"00",AL10="00"),CONCATENATE(AL9,"-",AM9))} -> ;H | AN11: {=_xlfn.IFS(AND(AN9="00",AN10="00"),";H",AND(AN9<>"00",AN10<>"00"),CONCATENATE(AN9,"-",AO10,"(",AO9,"-",AN10,")"),AND(AN9="00",AN10<>"00"),CONCATENATE(AN10,"-",AO10),AND(AN9<>"00",AN10="00"),CONCATENATE(AN9,"-",AO9))} -> ;H | AP11: {=_xlfn.IFS(AND(AP9="00",AP10="00"),";H",AND(AP9<>"00",AP10<>"00"),CONCATENATE(AP9,"-",AQ10,"(",AQ9,"-",AP10,")"),AND(AP9="00",AP10<>"00"),CONCATENATE(AP10,"-",AQ10),AND(AP9<>"00",AP10="00"),CONCATENATE(AP9,"-",AQ9))} -> ;H | AR11: {=_xlfn.IFS(AND(AR9="00",AR10="00"),";H",AND(AR9<>"00",AR10<>"00"),CONCATENATE(AR9,"-",AS10,"(",AS9,"-",AR10,")"),AND(AR9="00",AR10<>"00"),CONCATENATE(AR10,"-",AS10),AND(AR9<>"00",AR10="00"),CONCATENATE(AR9,"-",AS9))} -> ;H | AT11: {=_xlfn.IFS(AND(AT9="00",AT10="00"),";H",AND(AT9<>"00",AT10<>"00"),CONCATENATE(AT9,"-",AU10,"(",AU9,"-",AT10,")"),AND(AT9="00",AT10<>"00"),CONCATENATE(AT10,"-",AU10),AND(AT9<>"00",AT10="00"),CONCATENATE(AT9,"-",AU9))} -> ;H | AV11: {=_xlfn.IFS(AND(AV9="00",AV10="00"),";H",AND(AV9<>"00",AV10<>"00"),CONCATENATE(AV9,"-",AW10,"(",AW9,"-",AV10,")"),AND(AV9="00",AV10<>"00"),CONCATENATE(AV10,"-",AW10),AND(AV9<>"00",AV10="00"),CONCATENATE(AV9,"-",AW9))} -> ;H | AX11: {=_xlfn.IFS(AND(AX9="00",AX10="00"),";H",AND(AX9<>"00",AX10<>"00"),CONCATENATE(AX9,"-",AY10,"(",AY9,"-",AX10,")"),AND(AX9="00",AX10<>"00"),CONCATENATE(AX10,"-",AY10),AND(AX9<>"00",AX10="00"),CONCATENATE(AX9,"-",AY9))} -> ;H | AZ11: {=_xlfn.IFS(AND(AZ9="00",AZ10="00"),";H",AND(AZ9<>"00",AZ10<>"00"),CONCATENATE(AZ9,"-",BA10,"(",BA9,"-",AZ10,")"),AND(AZ9="00",AZ10<>"00"),CONCATENATE(AZ10,"-",BA10),AND(AZ9<>"00",AZ10="00"),CONCATENATE(AZ9,"-",BA9))} -> ;H | BB11: {=_xlfn.IFS(AND(BB9="00",BB10="00"),";H",AND(BB9<>"00",BB10<>"00"),CONCATENATE(BB9,"-",BC10,"(",BC9,"-",BB10,")"),AND(BB9="00",BB10<>"00"),CONCATENATE(BB10,"-",BC10),AND(BB9<>"00",BB10="00"),CONCATENATE(BB9,"-",BC9))} -> ;H | BD11: {=_xlfn.IFS(AND(BD9="00",BD10="00"),";H",AND(BD9<>"00",BD10<>"00"),CONCATENATE(BD9,"-",BE10,"(",BE9,"-",BD10,")"),AND(BD9="00",BD10<>"00"),CONCATENATE(BD10,"-",BE10),AND(BD9<>"00",BD10="00"),CONCATENATE(BD9,"-",BE9))} -> ;H | BF11: {=_xlfn.IFS(AND(BF9="00",BF10="00"),";H",AND(BF9<>"00",BF10<>"00"),CONCATENATE(BF9,"-",BG10,"(",BG9,"-",BF10,")"),AND(BF9="00",BF10<>"00"),CONCATENATE(BF10,"-",BG10),AND(BF9<>"00",BF10="00"),CONCATENATE(BF9,"-",BG9))} -> ;H | BH11: {=_xlfn.IFS(AND(BH9="00",BH10="00"),";H",AND(BH9<>"00",BH10<>"00"),CONCATENATE(BH9,"-",BI10,"(",BI9,"-",BH10,")"),AND(BH9="00",BH10<>"00"),CONCATENATE(BH10,"-",BI10),AND(BH9<>"00",BH10="00"),CONCATENATE(BH9,"-",BI9))} -> ;H | BJ11: {=_xlfn.IFS(AND(BJ9="00",BJ10="00"),";H",AND(BJ9<>"00",BJ10<>"00"),CONCATENATE(BJ9,"-",BK10,"(",BK9,"-",BJ10,")"),AND(BJ9="00",BJ10<>"00"),CONCATENATE(BJ10,"-",BK10),AND(BJ9<>"00",BJ10="00"),CONCATENATE(BJ9,"-",BK9))} -> ;H | BL11: {=_xlfn.IFS(AND(BL9="00",BL10="00"),";H",AND(BL9<>"00",BL10<>"00"),CONCATENATE(BL9,"-",BM10,"(",BM9,"-",BL10,")"),AND(BL9="00",BL10<>"00"),CONCATENATE(BL10,"-",BM10),AND(BL9<>"00",BL10="00"),CONCATENATE(BL9,"-",BM9))} -> ;H
B12: =整月外場班表!B12 -> 宋文馨 | D12: =IF(MOD(整月外場班表!D12,1)=0,CONCATENATE(整月外場班表!D12,"00"),CONCATENATE(INT(整月外場班表!D12),"30")) -> 00 | E12: =IF(MOD(整月外場班表!E12,1)=0,CONCATENATE(整月外場班表!E12,"00"),CONCATENATE(INT(整月外場班表!E12),"30")) -> 00 | F12: =IF(MOD(整月外場班表!F12,1)=0,CONCATENATE(整月外場班表!F12,"00"),CONCATENATE(INT(整月外場班表!F12),"30")) -> 00 | G12: =IF(MOD(整月外場班表!G12,1)=0,CONCATENATE(整月外場班表!G12,"00"),CONCATENATE(INT(整月外場班表!G12),"30")) -> 00 | H12: =IF(MOD(整月外場班表!H12,1)=0,CONCATENATE(整月外場班表!H12,"00"),CONCATENATE(INT(整月外場班表!H12),"30")) -> 00 | I12: =IF(MOD(整月外場班表!I12,1)=0,CONCATENATE(整月外場班表!I12,"00"),CONCATENATE(INT(整月外場班表!I12),"30")) -> 00 | J12: =IF(MOD(整月外場班表!J12,1)=0,CONCATENATE(整月外場班表!J12,"00"),CONCATENATE(INT(整月外場班表!J12),"30")) -> 00 | K12: =IF(MOD(整月外場班表!K12,1)=0,CONCATENATE(整月外場班表!K12,"00"),CONCATENATE(INT(整月外場班表!K12),"30")) -> 00 | ... BM12: =IF(MOD(整月外場班表!BM12,1)=0,CONCATENATE(整月外場班表!BM12,"00"),CONCATENATE(INT(整月外場班表!BM12),"30")) -> 00
D13: =IF(MOD(整月外場班表!D13,1)=0,CONCATENATE(整月外場班表!D13,"00"),CONCATENATE(INT(整月外場班表!D13),"30")) -> 00 | E13: =IF(MOD(整月外場班表!E13,1)=0,CONCATENATE(整月外場班表!E13,"00"),CONCATENATE(INT(整月外場班表!E13),"30")) -> 00 | F13: =IF(MOD(整月外場班表!F13,1)=0,CONCATENATE(整月外場班表!F13,"00"),CONCATENATE(INT(整月外場班表!F13),"30")) -> 00 | G13: =IF(MOD(整月外場班表!G13,1)=0,CONCATENATE(整月外場班表!G13,"00"),CONCATENATE(INT(整月外場班表!G13),"30")) -> 00 | H13: =IF(MOD(整月外場班表!H13,1)=0,CONCATENATE(整月外場班表!H13,"00"),CONCATENATE(INT(整月外場班表!H13),"30")) -> 00 | I13: =IF(MOD(整月外場班表!I13,1)=0,CONCATENATE(整月外場班表!I13,"00"),CONCATENATE(INT(整月外場班表!I13),"30")) -> 00 | J13: =IF(MOD(整月外場班表!J13,1)=0,CONCATENATE(整月外場班表!J13,"00"),CONCATENATE(INT(整月外場班表!J13),"30")) -> 00 | K13: =IF(MOD(整月外場班表!K13,1)=0,CONCATENATE(整月外場班表!K13,"00"),CONCATENATE(INT(整月外場班表!K13),"30")) -> 00 | ... BM13: =IF(MOD(整月外場班表!BM13,1)=0,CONCATENATE(整月外場班表!BM13,"00"),CONCATENATE(INT(整月外場班表!BM13),"30")) -> 00
D14: {=_xlfn.IFS(AND(D12="00",D13="00"),";H",AND(D12<>"00",D13<>"00"),CONCATENATE(D12,"-",E13,"(",E12,"-",D13,")"),AND(D12="00",D13<>"00"),CONCATENATE(D13,"-",E13),AND(D12<>"00",D13="00"),CONCATENATE(D12,"-",E12))} -> ;H | F14: {=_xlfn.IFS(AND(F12="00",F13="00"),";H",AND(F12<>"00",F13<>"00"),CONCATENATE(F12,"-",G13,"(",G12,"-",F13,")"),AND(F12="00",F13<>"00"),CONCATENATE(F13,"-",G13),AND(F12<>"00",F13="00"),CONCATENATE(F12,"-",G12))} -> ;H | H14: {=_xlfn.IFS(AND(H12="00",H13="00"),";H",AND(H12<>"00",H13<>"00"),CONCATENATE(H12,"-",I13,"(",I12,"-",H13,")"),AND(H12="00",H13<>"00"),CONCATENATE(H13,"-",I13),AND(H12<>"00",H13="00"),CONCATENATE(H12,"-",I12))} -> ;H | J14: {=_xlfn.IFS(AND(J12="00",J13="00"),";H",AND(J12<>"00",J13<>"00"),CONCATENATE(J12,"-",K13,"(",K12,"-",J13,")"),AND(J12="00",J13<>"00"),CONCATENATE(J13,"-",K13),AND(J12<>"00",J13="00"),CONCATENATE(J12,"-",K12))} -> ;H | L14: {=_xlfn.IFS(AND(L12="00",L13="00"),";H",AND(L12<>"00",L13<>"00"),CONCATENATE(L12,"-",M13,"(",M12,"-",L13,")"),AND(L12="00",L13<>"00"),CONCATENATE(L13,"-",M13),AND(L12<>"00",L13="00"),CONCATENATE(L12,"-",M12))} -> ;H | N14: {=_xlfn.IFS(AND(N12="00",N13="00"),";H",AND(N12<>"00",N13<>"00"),CONCATENATE(N12,"-",O13,"(",O12,"-",N13,")"),AND(N12="00",N13<>"00"),CONCATENATE(N13,"-",O13),AND(N12<>"00",N13="00"),CONCATENATE(N12,"-",O12))} -> ;H | P14: {=_xlfn.IFS(AND(P12="00",P13="00"),";H",AND(P12<>"00",P13<>"00"),CONCATENATE(P12,"-",Q13,"(",Q12,"-",P13,")"),AND(P12="00",P13<>"00"),CONCATENATE(P13,"-",Q13),AND(P12<>"00",P13="00"),CONCATENATE(P12,"-",Q12))} -> ;H | R14: {=_xlfn.IFS(AND(R12="00",R13="00"),";H",AND(R12<>"00",R13<>"00"),CONCATENATE(R12,"-",S13,"(",S12,"-",R13,")"),AND(R12="00",R13<>"00"),CONCATENATE(R13,"-",S13),AND(R12<>"00",R13="00"),CONCATENATE(R12,"-",S12))} -> ;H | T14: {=_xlfn.IFS(AND(T12="00",T13="00"),";H",AND(T12<>"00",T13<>"00"),CONCATENATE(T12,"-",U13,"(",U12,"-",T13,")"),AND(T12="00",T13<>"00"),CONCATENATE(T13,"-",U13),AND(T12<>"00",T13="00"),CONCATENATE(T12,"-",U12))} -> ;H | V14: {=_xlfn.IFS(AND(V12="00",V13="00"),";H",AND(V12<>"00",V13<>"00"),CONCATENATE(V12,"-",W13,"(",W12,"-",V13,")"),AND(V12="00",V13<>"00"),CONCATENATE(V13,"-",W13),AND(V12<>"00",V13="00"),CONCATENATE(V12,"-",W12))} -> ;H | X14: {=_xlfn.IFS(AND(X12="00",X13="00"),";H",AND(X12<>"00",X13<>"00"),CONCATENATE(X12,"-",Y13,"(",Y12,"-",X13,")"),AND(X12="00",X13<>"00"),CONCATENATE(X13,"-",Y13),AND(X12<>"00",X13="00"),CONCATENATE(X12,"-",Y12))} -> ;H | Z14: {=_xlfn.IFS(AND(Z12="00",Z13="00"),";H",AND(Z12<>"00",Z13<>"00"),CONCATENATE(Z12,"-",AA13,"(",AA12,"-",Z13,")"),AND(Z12="00",Z13<>"00"),CONCATENATE(Z13,"-",AA13),AND(Z12<>"00",Z13="00"),CONCATENATE(Z12,"-",AA12))} -> ;H | AB14: {=_xlfn.IFS(AND(AB12="00",AB13="00"),";H",AND(AB12<>"00",AB13<>"00"),CONCATENATE(AB12,"-",AC13,"(",AC12,"-",AB13,")"),AND(AB12="00",AB13<>"00"),CONCATENATE(AB13,"-",AC13),AND(AB12<>"00",AB13="00"),CONCATENATE(AB12,"-",AC12))} -> ;H | AD14: {=_xlfn.IFS(AND(AD12="00",AD13="00"),";H",AND(AD12<>"00",AD13<>"00"),CONCATENATE(AD12,"-",AE13,"(",AE12,"-",AD13,")"),AND(AD12="00",AD13<>"00"),CONCATENATE(AD13,"-",AE13),AND(AD12<>"00",AD13="00"),CONCATENATE(AD12,"-",AE12))} -> ;H | AF14: {=_xlfn.IFS(AND(AF12="00",AF13="00"),";H",AND(AF12<>"00",AF13<>"00"),CONCATENATE(AF12,"-",AG13,"(",AG12,"-",AF13,")"),AND(AF12="00",AF13<>"00"),CONCATENATE(AF13,"-",AG13),AND(AF12<>"00",AF13="00"),CONCATENATE(AF12,"-",AG12))} -> ;H | AH14: {=_xlfn.IFS(AND(AH12="00",AH13="00"),";H",AND(AH12<>"00",AH13<>"00"),CONCATENATE(AH12,"-",AI13,"(",AI12,"-",AH13,")"),AND(AH12="00",AH13<>"00"),CONCATENATE(AH13,"-",AI13),AND(AH12<>"00",AH13="00"),CONCATENATE(AH12,"-",AI12))} -> ;H | AJ14: {=_xlfn.IFS(AND(AJ12="00",AJ13="00"),";H",AND(AJ12<>"00",AJ13<>"00"),CONCATENATE(AJ12,"-",AK13,"(",AK12,"-",AJ13,")"),AND(AJ12="00",AJ13<>"00"),CONCATENATE(AJ13,"-",AK13),AND(AJ12<>"00",AJ13="00"),CONCATENATE(AJ12,"-",AK12))} -> ;H | AL14: {=_xlfn.IFS(AND(AL12="00",AL13="00"),";H",AND(AL12<>"00",AL13<>"00"),CONCATENATE(AL12,"-",AM13,"(",AM12,"-",AL13,")"),AND(AL12="00",AL13<>"00"),CONCATENATE(AL13,"-",AM13),AND(AL12<>"00",AL13="00"),CONCATENATE(AL12,"-",AM12))} -> ;H | AN14: {=_xlfn.IFS(AND(AN12="00",AN13="00"),";H",AND(AN12<>"00",AN13<>"00"),CONCATENATE(AN12,"-",AO13,"(",AO12,"-",AN13,")"),AND(AN12="00",AN13<>"00"),CONCATENATE(AN13,"-",AO13),AND(AN12<>"00",AN13="00"),CONCATENATE(AN12,"-",AO12))} -> ;H | AP14: {=_xlfn.IFS(AND(AP12="00",AP13="00"),";H",AND(AP12<>"00",AP13<>"00"),CONCATENATE(AP12,"-",AQ13,"(",AQ12,"-",AP13,")"),AND(AP12="00",AP13<>"00"),CONCATENATE(AP13,"-",AQ13),AND(AP12<>"00",AP13="00"),CONCATENATE(AP12,"-",AQ12))} -> ;H | AR14: {=_xlfn.IFS(AND(AR12="00",AR13="00"),";H",AND(AR12<>"00",AR13<>"00"),CONCATENATE(AR12,"-",AS13,"(",AS12,"-",AR13,")"),AND(AR12="00",AR13<>"00"),CONCATENATE(AR13,"-",AS13),AND(AR12<>"00",AR13="00"),CONCATENATE(AR12,"-",AS12))} -> ;H | AT14: {=_xlfn.IFS(AND(AT12="00",AT13="00"),";H",AND(AT12<>"00",AT13<>"00"),CONCATENATE(AT12,"-",AU13,"(",AU12,"-",AT13,")"),AND(AT12="00",AT13<>"00"),CONCATENATE(AT13,"-",AU13),AND(AT12<>"00",AT13="00"),CONCATENATE(AT12,"-",AU12))} -> ;H | AV14: {=_xlfn.IFS(AND(AV12="00",AV13="00"),";H",AND(AV12<>"00",AV13<>"00"),CONCATENATE(AV12,"-",AW13,"(",AW12,"-",AV13,")"),AND(AV12="00",AV13<>"00"),CONCATENATE(AV13,"-",AW13),AND(AV12<>"00",AV13="00"),CONCATENATE(AV12,"-",AW12))} -> ;H | AX14: {=_xlfn.IFS(AND(AX12="00",AX13="00"),";H",AND(AX12<>"00",AX13<>"00"),CONCATENATE(AX12,"-",AY13,"(",AY12,"-",AX13,")"),AND(AX12="00",AX13<>"00"),CONCATENATE(AX13,"-",AY13),AND(AX12<>"00",AX13="00"),CONCATENATE(AX12,"-",AY12))} -> ;H | AZ14: {=_xlfn.IFS(AND(AZ12="00",AZ13="00"),";H",AND(AZ12<>"00",AZ13<>"00"),CONCATENATE(AZ12,"-",BA13,"(",BA12,"-",AZ13,")"),AND(AZ12="00",AZ13<>"00"),CONCATENATE(AZ13,"-",BA13),AND(AZ12<>"00",AZ13="00"),CONCATENATE(AZ12,"-",BA12))} -> ;H | BB14: {=_xlfn.IFS(AND(BB12="00",BB13="00"),";H",AND(BB12<>"00",BB13<>"00"),CONCATENATE(BB12,"-",BC13,"(",BC12,"-",BB13,")"),AND(BB12="00",BB13<>"00"),CONCATENATE(BB13,"-",BC13),AND(BB12<>"00",BB13="00"),CONCATENATE(BB12,"-",BC12))} -> ;H | BD14: {=_xlfn.IFS(AND(BD12="00",BD13="00"),";H",AND(BD12<>"00",BD13<>"00"),CONCATENATE(BD12,"-",BE13,"(",BE12,"-",BD13,")"),AND(BD12="00",BD13<>"00"),CONCATENATE(BD13,"-",BE13),AND(BD12<>"00",BD13="00"),CONCATENATE(BD12,"-",BE12))} -> ;H | BF14: {=_xlfn.IFS(AND(BF12="00",BF13="00"),";H",AND(BF12<>"00",BF13<>"00"),CONCATENATE(BF12,"-",BG13,"(",BG12,"-",BF13,")"),AND(BF12="00",BF13<>"00"),CONCATENATE(BF13,"-",BG13),AND(BF12<>"00",BF13="00"),CONCATENATE(BF12,"-",BG12))} -> ;H | BH14: {=_xlfn.IFS(AND(BH12="00",BH13="00"),";H",AND(BH12<>"00",BH13<>"00"),CONCATENATE(BH12,"-",BI13,"(",BI12,"-",BH13,")"),AND(BH12="00",BH13<>"00"),CONCATENATE(BH13,"-",BI13),AND(BH12<>"00",BH13="00"),CONCATENATE(BH12,"-",BI12))} -> ;H | BJ14: {=_xlfn.IFS(AND(BJ12="00",BJ13="00"),";H",AND(BJ12<>"00",BJ13<>"00"),CONCATENATE(BJ12,"-",BK13,"(",BK12,"-",BJ13,")"),AND(BJ12="00",BJ13<>"00"),CONCATENATE(BJ13,"-",BK13),AND(BJ12<>"00",BJ13="00"),CONCATENATE(BJ12,"-",BK12))} -> ;H | BL14: {=_xlfn.IFS(AND(BL12="00",BL13="00"),";H",AND(BL12<>"00",BL13<>"00"),CONCATENATE(BL12,"-",BM13,"(",BM12,"-",BL13,")"),AND(BL12="00",BL13<>"00"),CONCATENATE(BL13,"-",BM13),AND(BL12<>"00",BL13="00"),CONCATENATE(BL12,"-",BM12))} -> ;H
B15: =整月外場班表!B15 -> 程楚茜 | D15: =IF(MOD(整月外場班表!D15,1)=0,CONCATENATE(整月外場班表!D15,"00"),CONCATENATE(INT(整月外場班表!D15),"30")) -> 00 | E15: =IF(MOD(整月外場班表!E15,1)=0,CONCATENATE(整月外場班表!E15,"00"),CONCATENATE(INT(整月外場班表!E15),"30")) -> 00 | F15: =IF(MOD(整月外場班表!F15,1)=0,CONCATENATE(整月外場班表!F15,"00"),CONCATENATE(INT(整月外場班表!F15),"30")) -> 00 | G15: =IF(MOD(整月外場班表!G15,1)=0,CONCATENATE(整月外場班表!G15,"00"),CONCATENATE(INT(整月外場班表!G15),"30")) -> 00 | H15: =IF(MOD(整月外場班表!H15,1)=0,CONCATENATE(整月外場班表!H15,"00"),CONCATENATE(INT(整月外場班表!H15),"30")) -> 00 | I15: =IF(MOD(整月外場班表!I15,1)=0,CONCATENATE(整月外場班表!I15,"00"),CONCATENATE(INT(整月外場班表!I15),"30")) -> 00 | J15: =IF(MOD(整月外場班表!J15,1)=0,CONCATENATE(整月外場班表!J15,"00"),CONCATENATE(INT(整月外場班表!J15),"30")) -> 00 | K15: =IF(MOD(整月外場班表!K15,1)=0,CONCATENATE(整月外場班表!K15,"00"),CONCATENATE(INT(整月外場班表!K15),"30")) -> 00 | ... BM15: =IF(MOD(整月外場班表!BM15,1)=0,CONCATENATE(整月外場班表!BM15,"00"),CONCATENATE(INT(整月外場班表!BM15),"30")) -> 00
D16: =IF(MOD(整月外場班表!D16,1)=0,CONCATENATE(整月外場班表!D16,"00"),CONCATENATE(INT(整月外場班表!D16),"30")) -> 00 | E16: =IF(MOD(整月外場班表!E16,1)=0,CONCATENATE(整月外場班表!E16,"00"),CONCATENATE(INT(整月外場班表!E16),"30")) -> 00 | F16: =IF(MOD(整月外場班表!F16,1)=0,CONCATENATE(整月外場班表!F16,"00"),CONCATENATE(INT(整月外場班表!F16),"30")) -> 00 | G16: =IF(MOD(整月外場班表!G16,1)=0,CONCATENATE(整月外場班表!G16,"00"),CONCATENATE(INT(整月外場班表!G16),"30")) -> 00 | H16: =IF(MOD(整月外場班表!H16,1)=0,CONCATENATE(整月外場班表!H16,"00"),CONCATENATE(INT(整月外場班表!H16),"30")) -> 00 | I16: =IF(MOD(整月外場班表!I16,1)=0,CONCATENATE(整月外場班表!I16,"00"),CONCATENATE(INT(整月外場班表!I16),"30")) -> 00 | J16: =IF(MOD(整月外場班表!J16,1)=0,CONCATENATE(整月外場班表!J16,"00"),CONCATENATE(INT(整月外場班表!J16),"30")) -> 00 | K16: =IF(MOD(整月外場班表!K16,1)=0,CONCATENATE(整月外場班表!K16,"00"),CONCATENATE(INT(整月外場班表!K16),"30")) -> 00 | ... BM16: =IF(MOD(整月外場班表!BM16,1)=0,CONCATENATE(整月外場班表!BM16,"00"),CONCATENATE(INT(整月外場班表!BM16),"30")) -> 00
D17: {=_xlfn.IFS(AND(D15="00",D16="00"),";H",AND(D15<>"00",D16<>"00"),CONCATENATE(D15,"-",E16,"(",E15,"-",D16,")"),AND(D15="00",D16<>"00"),CONCATENATE(D16,"-",E16),AND(D15<>"00",D16="00"),CONCATENATE(D15,"-",E15))} -> ;H | F17: {=_xlfn.IFS(AND(F15="00",F16="00"),";H",AND(F15<>"00",F16<>"00"),CONCATENATE(F15,"-",G16,"(",G15,"-",F16,")"),AND(F15="00",F16<>"00"),CONCATENATE(F16,"-",G16),AND(F15<>"00",F16="00"),CONCATENATE(F15,"-",G15))} -> ;H | H17: {=_xlfn.IFS(AND(H15="00",H16="00"),";H",AND(H15<>"00",H16<>"00"),CONCATENATE(H15,"-",I16,"(",I15,"-",H16,")"),AND(H15="00",H16<>"00"),CONCATENATE(H16,"-",I16),AND(H15<>"00",H16="00"),CONCATENATE(H15,"-",I15))} -> ;H | J17: {=_xlfn.IFS(AND(J15="00",J16="00"),";H",AND(J15<>"00",J16<>"00"),CONCATENATE(J15,"-",K16,"(",K15,"-",J16,")"),AND(J15="00",J16<>"00"),CONCATENATE(J16,"-",K16),AND(J15<>"00",J16="00"),CONCATENATE(J15,"-",K15))} -> ;H | L17: {=_xlfn.IFS(AND(L15="00",L16="00"),";H",AND(L15<>"00",L16<>"00"),CONCATENATE(L15,"-",M16,"(",M15,"-",L16,")"),AND(L15="00",L16<>"00"),CONCATENATE(L16,"-",M16),AND(L15<>"00",L16="00"),CONCATENATE(L15,"-",M15))} -> ;H | N17: {=_xlfn.IFS(AND(N15="00",N16="00"),";H",AND(N15<>"00",N16<>"00"),CONCATENATE(N15,"-",O16,"(",O15,"-",N16,")"),AND(N15="00",N16<>"00"),CONCATENATE(N16,"-",O16),AND(N15<>"00",N16="00"),CONCATENATE(N15,"-",O15))} -> ;H | P17: {=_xlfn.IFS(AND(P15="00",P16="00"),";H",AND(P15<>"00",P16<>"00"),CONCATENATE(P15,"-",Q16,"(",Q15,"-",P16,")"),AND(P15="00",P16<>"00"),CONCATENATE(P16,"-",Q16),AND(P15<>"00",P16="00"),CONCATENATE(P15,"-",Q15))} -> ;H | R17: {=_xlfn.IFS(AND(R15="00",R16="00"),";H",AND(R15<>"00",R16<>"00"),CONCATENATE(R15,"-",S16,"(",S15,"-",R16,")"),AND(R15="00",R16<>"00"),CONCATENATE(R16,"-",S16),AND(R15<>"00",R16="00"),CONCATENATE(R15,"-",S15))} -> ;H | T17: {=_xlfn.IFS(AND(T15="00",T16="00"),";H",AND(T15<>"00",T16<>"00"),CONCATENATE(T15,"-",U16,"(",U15,"-",T16,")"),AND(T15="00",T16<>"00"),CONCATENATE(T16,"-",U16),AND(T15<>"00",T16="00"),CONCATENATE(T15,"-",U15))} -> ;H | V17: {=_xlfn.IFS(AND(V15="00",V16="00"),";H",AND(V15<>"00",V16<>"00"),CONCATENATE(V15,"-",W16,"(",W15,"-",V16,")"),AND(V15="00",V16<>"00"),CONCATENATE(V16,"-",W16),AND(V15<>"00",V16="00"),CONCATENATE(V15,"-",W15))} -> ;H | X17: {=_xlfn.IFS(AND(X15="00",X16="00"),";H",AND(X15<>"00",X16<>"00"),CONCATENATE(X15,"-",Y16,"(",Y15,"-",X16,")"),AND(X15="00",X16<>"00"),CONCATENATE(X16,"-",Y16),AND(X15<>"00",X16="00"),CONCATENATE(X15,"-",Y15))} -> ;H | Z17: {=_xlfn.IFS(AND(Z15="00",Z16="00"),";H",AND(Z15<>"00",Z16<>"00"),CONCATENATE(Z15,"-",AA16,"(",AA15,"-",Z16,")"),AND(Z15="00",Z16<>"00"),CONCATENATE(Z16,"-",AA16),AND(Z15<>"00",Z16="00"),CONCATENATE(Z15,"-",AA15))} -> ;H | AB17: {=_xlfn.IFS(AND(AB15="00",AB16="00"),";H",AND(AB15<>"00",AB16<>"00"),CONCATENATE(AB15,"-",AC16,"(",AC15,"-",AB16,")"),AND(AB15="00",AB16<>"00"),CONCATENATE(AB16,"-",AC16),AND(AB15<>"00",AB16="00"),CONCATENATE(AB15,"-",AC15))} -> ;H | AD17: {=_xlfn.IFS(AND(AD15="00",AD16="00"),";H",AND(AD15<>"00",AD16<>"00"),CONCATENATE(AD15,"-",AE16,"(",AE15,"-",AD16,")"),AND(AD15="00",AD16<>"00"),CONCATENATE(AD16,"-",AE16),AND(AD15<>"00",AD16="00"),CONCATENATE(AD15,"-",AE15))} -> ;H | AF17: {=_xlfn.IFS(AND(AF15="00",AF16="00"),";H",AND(AF15<>"00",AF16<>"00"),CONCATENATE(AF15,"-",AG16,"(",AG15,"-",AF16,")"),AND(AF15="00",AF16<>"00"),CONCATENATE(AF16,"-",AG16),AND(AF15<>"00",AF16="00"),CONCATENATE(AF15,"-",AG15))} -> ;H | AH17: {=_xlfn.IFS(AND(AH15="00",AH16="00"),";H",AND(AH15<>"00",AH16<>"00"),CONCATENATE(AH15,"-",AI16,"(",AI15,"-",AH16,")"),AND(AH15="00",AH16<>"00"),CONCATENATE(AH16,"-",AI16),AND(AH15<>"00",AH16="00"),CONCATENATE(AH15,"-",AI15))} -> ;H | AJ17: {=_xlfn.IFS(AND(AJ15="00",AJ16="00"),";H",AND(AJ15<>"00",AJ16<>"00"),CONCATENATE(AJ15,"-",AK16,"(",AK15,"-",AJ16,")"),AND(AJ15="00",AJ16<>"00"),CONCATENATE(AJ16,"-",AK16),AND(AJ15<>"00",AJ16="00"),CONCATENATE(AJ15,"-",AK15))} -> ;H | AL17: {=_xlfn.IFS(AND(AL15="00",AL16="00"),";H",AND(AL15<>"00",AL16<>"00"),CONCATENATE(AL15,"-",AM16,"(",AM15,"-",AL16,")"),AND(AL15="00",AL16<>"00"),CONCATENATE(AL16,"-",AM16),AND(AL15<>"00",AL16="00"),CONCATENATE(AL15,"-",AM15))} -> ;H | AN17: {=_xlfn.IFS(AND(AN15="00",AN16="00"),";H",AND(AN15<>"00",AN16<>"00"),CONCATENATE(AN15,"-",AO16,"(",AO15,"-",AN16,")"),AND(AN15="00",AN16<>"00"),CONCATENATE(AN16,"-",AO16),AND(AN15<>"00",AN16="00"),CONCATENATE(AN15,"-",AO15))} -> ;H | AP17: {=_xlfn.IFS(AND(AP15="00",AP16="00"),";H",AND(AP15<>"00",AP16<>"00"),CONCATENATE(AP15,"-",AQ16,"(",AQ15,"-",AP16,")"),AND(AP15="00",AP16<>"00"),CONCATENATE(AP16,"-",AQ16),AND(AP15<>"00",AP16="00"),CONCATENATE(AP15,"-",AQ15))} -> ;H | AR17: {=_xlfn.IFS(AND(AR15="00",AR16="00"),";H",AND(AR15<>"00",AR16<>"00"),CONCATENATE(AR15,"-",AS16,"(",AS15,"-",AR16,")"),AND(AR15="00",AR16<>"00"),CONCATENATE(AR16,"-",AS16),AND(AR15<>"00",AR16="00"),CONCATENATE(AR15,"-",AS15))} -> ;H | AT17: {=_xlfn.IFS(AND(AT15="00",AT16="00"),";H",AND(AT15<>"00",AT16<>"00"),CONCATENATE(AT15,"-",AU16,"(",AU15,"-",AT16,")"),AND(AT15="00",AT16<>"00"),CONCATENATE(AT16,"-",AU16),AND(AT15<>"00",AT16="00"),CONCATENATE(AT15,"-",AU15))} -> ;H | AV17: {=_xlfn.IFS(AND(AV15="00",AV16="00"),";H",AND(AV15<>"00",AV16<>"00"),CONCATENATE(AV15,"-",AW16,"(",AW15,"-",AV16,")"),AND(AV15="00",AV16<>"00"),CONCATENATE(AV16,"-",AW16),AND(AV15<>"00",AV16="00"),CONCATENATE(AV15,"-",AW15))} -> ;H | AX17: {=_xlfn.IFS(AND(AX15="00",AX16="00"),";H",AND(AX15<>"00",AX16<>"00"),CONCATENATE(AX15,"-",AY16,"(",AY15,"-",AX16,")"),AND(AX15="00",AX16<>"00"),CONCATENATE(AX16,"-",AY16),AND(AX15<>"00",AX16="00"),CONCATENATE(AX15,"-",AY15))} -> ;H | AZ17: {=_xlfn.IFS(AND(AZ15="00",AZ16="00"),";H",AND(AZ15<>"00",AZ16<>"00"),CONCATENATE(AZ15,"-",BA16,"(",BA15,"-",AZ16,")"),AND(AZ15="00",AZ16<>"00"),CONCATENATE(AZ16,"-",BA16),AND(AZ15<>"00",AZ16="00"),CONCATENATE(AZ15,"-",BA15))} -> ;H | BB17: {=_xlfn.IFS(AND(BB15="00",BB16="00"),";H",AND(BB15<>"00",BB16<>"00"),CONCATENATE(BB15,"-",BC16,"(",BC15,"-",BB16,")"),AND(BB15="00",BB16<>"00"),CONCATENATE(BB16,"-",BC16),AND(BB15<>"00",BB16="00"),CONCATENATE(BB15,"-",BC15))} -> ;H | BD17: {=_xlfn.IFS(AND(BD15="00",BD16="00"),";H",AND(BD15<>"00",BD16<>"00"),CONCATENATE(BD15,"-",BE16,"(",BE15,"-",BD16,")"),AND(BD15="00",BD16<>"00"),CONCATENATE(BD16,"-",BE16),AND(BD15<>"00",BD16="00"),CONCATENATE(BD15,"-",BE15))} -> ;H | BF17: {=_xlfn.IFS(AND(BF15="00",BF16="00"),";H",AND(BF15<>"00",BF16<>"00"),CONCATENATE(BF15,"-",BG16,"(",BG15,"-",BF16,")"),AND(BF15="00",BF16<>"00"),CONCATENATE(BF16,"-",BG16),AND(BF15<>"00",BF16="00"),CONCATENATE(BF15,"-",BG15))} -> ;H | BH17: {=_xlfn.IFS(AND(BH15="00",BH16="00"),";H",AND(BH15<>"00",BH16<>"00"),CONCATENATE(BH15,"-",BI16,"(",BI15,"-",BH16,")"),AND(BH15="00",BH16<>"00"),CONCATENATE(BH16,"-",BI16),AND(BH15<>"00",BH16="00"),CONCATENATE(BH15,"-",BI15))} -> ;H | BJ17: {=_xlfn.IFS(AND(BJ15="00",BJ16="00"),";H",AND(BJ15<>"00",BJ16<>"00"),CONCATENATE(BJ15,"-",BK16,"(",BK15,"-",BJ16,")"),AND(BJ15="00",BJ16<>"00"),CONCATENATE(BJ16,"-",BK16),AND(BJ15<>"00",BJ16="00"),CONCATENATE(BJ15,"-",BK15))} -> ;H | BL17: {=_xlfn.IFS(AND(BL15="00",BL16="00"),";H",AND(BL15<>"00",BL16<>"00"),CONCATENATE(BL15,"-",BM16,"(",BM15,"-",BL16,")"),AND(BL15="00",BL16<>"00"),CONCATENATE(BL16,"-",BM16),AND(BL15<>"00",BL16="00"),CONCATENATE(BL15,"-",BM15))} -> ;H
